2021-04-22 07:16:29,484:INFO:PyCaret Supervised Module
2021-04-22 07:16:29,484:INFO:ML Usecase: regression
2021-04-22 07:16:29,484:INFO:version 2.3.0
2021-04-22 07:16:29,484:INFO:Initializing setup()
2021-04-22 07:16:29,484:INFO:setup(target=IRI, ml_usecase=regression, available_plots={'parameter': 'Hyperparameters', 'residuals': 'Residuals', 'error': 'Prediction Error', 'cooks': 'Cooks Distance', 'rfe': 'Feature Selection', 'learning': 'Learning Curve', 'manifold': 'Manifold Learning', 'vc': 'Validation Curve', 'feature': 'Feature Importance', 'feature_all': 'Feature Importance (All)', 'tree': 'Decision Tree', 'residuals_interactive': 'Interactive Residuals'}, train_size=0.7, test_data=None, preprocess=True, imputation_type=simple, iterative_imputation_iters=5, categorical_features=None, categorical_imputation=constant, categorical_iterative_imputer=lightgbm, ordinal_features=None, high_cardinality_features=None, high_cardinality_method=frequency, numeric_features=None, numeric_imputation=mean, numeric_iterative_imputer=lightgbm, date_features=None, ignore_features=None, normalize=False, normalize_method=zscore, transformation=False, transformation_method=yeo-johnson, handle_unknown_categorical=True, unknown_categorical_method=least_frequent, pca=False, pca_method=linear, pca_components=None, ignore_low_variance=False, combine_rare_levels=False, rare_level_threshold=0.1, bin_numeric_features=None, remove_outliers=False, outliers_threshold=0.05, remove_multicollinearity=False, multicollinearity_threshold=0.9, remove_perfect_collinearity=True, create_clusters=False, cluster_iter=20, polynomial_features=False, polynomial_degree=2, trigonometry_features=False, polynomial_threshold=0.1, group_features=None, group_names=None, feature_selection=False, feature_selection_threshold=0.8, feature_selection_method=classic, feature_interaction=False, feature_ratio=False, interaction_threshold=0.01, fix_imbalance=False, fix_imbalance_method=None, transform_target=False, transform_target_method=box-cox, data_split_shuffle=True, data_split_stratify=False, fold_strategy=kfold, fold=10, fold_shuffle=False, fold_groups=None, n_jobs=-1, use_gpu=False, custom_pipeline=None, html=True, session_id=None, log_experiment=False, experiment_name=None, log_plots=False, log_profile=False, log_data=False, silent=False, verbose=True, profile=False, profile_kwargs=None, display=None)
2021-04-22 07:16:29,484:INFO:Checking environment
2021-04-22 07:16:29,485:INFO:python_version: 3.8.8
2021-04-22 07:16:29,485:INFO:python_build: ('tags/v3.8.8:024d805', 'Feb 19 2021 13:18:16')
2021-04-22 07:16:29,485:INFO:machine: AMD64
2021-04-22 07:16:29,485:INFO:platform: Windows-10-10.0.18362-SP0
2021-04-22 07:16:29,485:WARNING:cannot find psutil installation. memory not traceable. Install psutil using pip to enable memory logging.
2021-04-22 07:16:29,485:INFO:Checking libraries
2021-04-22 07:16:29,486:INFO:pd==1.2.4
2021-04-22 07:16:29,486:INFO:numpy==1.19.5
2021-04-22 07:16:29,486:INFO:sklearn==0.23.2
2021-04-22 07:16:29,486:INFO:lightgbm==3.2.1
2021-04-22 07:16:29,486:WARNING:catboost not found
2021-04-22 07:16:29,487:WARNING:xgboost not found
2021-04-22 07:16:29,770:INFO:mlflow==1.15.0
2021-04-22 07:16:29,770:INFO:Checking Exceptions
2021-04-22 07:16:29,770:INFO:Declaring global variables
2021-04-22 07:16:29,770:INFO:USI: 1ddd
2021-04-22 07:16:29,770:INFO:pycaret_globals: {'_ml_usecase', 'seed', 'X', 'display_container', '_all_metrics', 'fix_imbalance_method_param', 'y_test', 'imputation_classifier', 'fold_param', 'X_train', 'prep_pipe', 'logging_param', 'imputation_regressor', 'exp_name_log', 'y_train', '_internal_pipeline', 'X_test', 'pycaret_globals', 'fold_groups_param', 'USI', 'gpu_param', '_available_plots', 'target_param', 'master_model_container', 'html_param', 'n_jobs_param', 'fold_shuffle_param', '_all_models_internal', 'data_before_preprocess', 'transform_target_method_param', '_all_models', '_gpu_n_jobs_param', 'y', 'log_plots_param', 'create_model_container', 'stratify_param', 'transform_target_param', 'iterative_imputation_iters_param', 'fold_generator', 'experiment__', 'fix_imbalance_param'}
2021-04-22 07:16:29,770:INFO:Preparing display monitor
2021-04-22 07:16:29,770:INFO:Preparing display monitor
2021-04-22 07:16:29,775:INFO:Importing libraries
2021-04-22 07:16:29,775:INFO:Copying data for preprocessing
2021-04-22 07:16:29,777:INFO:Declaring preprocessing parameters
2021-04-22 07:16:29,778:INFO:Creating preprocessing pipeline
2021-04-22 07:16:29,792:INFO:Preprocessing pipeline created successfully
2021-04-22 07:16:29,792:ERROR:(Process Exit): setup has been interupted with user command 'quit'. setup must rerun.
2021-04-22 07:16:29,792:INFO:Creating global containers
2021-04-22 07:16:29,793:INFO:Internal pipeline: Pipeline(memory=None, steps=[('empty_step', 'passthrough')], verbose=False)
2021-04-22 07:18:59,017:INFO:PyCaret Supervised Module
2021-04-22 07:18:59,017:INFO:ML Usecase: regression
2021-04-22 07:18:59,017:INFO:version 2.3.0
2021-04-22 07:18:59,017:INFO:Initializing setup()
2021-04-22 07:18:59,017:INFO:setup(target=Numeric, ml_usecase=regression, available_plots={'parameter': 'Hyperparameters', 'residuals': 'Residuals', 'error': 'Prediction Error', 'cooks': 'Cooks Distance', 'rfe': 'Feature Selection', 'learning': 'Learning Curve', 'manifold': 'Manifold Learning', 'vc': 'Validation Curve', 'feature': 'Feature Importance', 'feature_all': 'Feature Importance (All)', 'tree': 'Decision Tree', 'residuals_interactive': 'Interactive Residuals'}, train_size=0.7, test_data=None, preprocess=True, imputation_type=simple, iterative_imputation_iters=5, categorical_features=None, categorical_imputation=constant, categorical_iterative_imputer=lightgbm, ordinal_features=None, high_cardinality_features=None, high_cardinality_method=frequency, numeric_features=None, numeric_imputation=mean, numeric_iterative_imputer=lightgbm, date_features=None, ignore_features=None, normalize=False, normalize_method=zscore, transformation=False, transformation_method=yeo-johnson, handle_unknown_categorical=True, unknown_categorical_method=least_frequent, pca=False, pca_method=linear, pca_components=None, ignore_low_variance=False, combine_rare_levels=False, rare_level_threshold=0.1, bin_numeric_features=None, remove_outliers=False, outliers_threshold=0.05, remove_multicollinearity=False, multicollinearity_threshold=0.9, remove_perfect_collinearity=True, create_clusters=False, cluster_iter=20, polynomial_features=False, polynomial_degree=2, trigonometry_features=False, polynomial_threshold=0.1, group_features=None, group_names=None, feature_selection=False, feature_selection_threshold=0.8, feature_selection_method=classic, feature_interaction=False, feature_ratio=False, interaction_threshold=0.01, fix_imbalance=False, fix_imbalance_method=None, transform_target=False, transform_target_method=box-cox, data_split_shuffle=True, data_split_stratify=False, fold_strategy=kfold, fold=10, fold_shuffle=False, fold_groups=None, n_jobs=-1, use_gpu=False, custom_pipeline=None, html=True, session_id=None, log_experiment=False, experiment_name=None, log_plots=False, log_profile=False, log_data=False, silent=False, verbose=True, profile=False, profile_kwargs=None, display=None)
2021-04-22 07:18:59,017:INFO:Checking environment
2021-04-22 07:18:59,017:INFO:python_version: 3.8.8
2021-04-22 07:18:59,017:INFO:python_build: ('tags/v3.8.8:024d805', 'Feb 19 2021 13:18:16')
2021-04-22 07:18:59,017:INFO:machine: AMD64
2021-04-22 07:18:59,017:INFO:platform: Windows-10-10.0.18362-SP0
2021-04-22 07:18:59,018:WARNING:cannot find psutil installation. memory not traceable. Install psutil using pip to enable memory logging.
2021-04-22 07:18:59,018:INFO:Checking libraries
2021-04-22 07:18:59,018:INFO:pd==1.2.4
2021-04-22 07:18:59,018:INFO:numpy==1.19.5
2021-04-22 07:18:59,018:INFO:sklearn==0.23.2
2021-04-22 07:18:59,018:INFO:lightgbm==3.2.1
2021-04-22 07:18:59,019:WARNING:catboost not found
2021-04-22 07:18:59,019:WARNING:xgboost not found
2021-04-22 07:18:59,278:INFO:mlflow==1.15.0
2021-04-22 07:18:59,278:INFO:Checking Exceptions
2021-04-22 07:19:10,207:INFO:PyCaret Supervised Module
2021-04-22 07:19:10,207:INFO:ML Usecase: regression
2021-04-22 07:19:10,207:INFO:version 2.3.0
2021-04-22 07:19:10,207:INFO:Initializing setup()
2021-04-22 07:19:10,207:INFO:setup(target=IWP IRI, ml_usecase=regression, available_plots={'parameter': 'Hyperparameters', 'residuals': 'Residuals', 'error': 'Prediction Error', 'cooks': 'Cooks Distance', 'rfe': 'Feature Selection', 'learning': 'Learning Curve', 'manifold': 'Manifold Learning', 'vc': 'Validation Curve', 'feature': 'Feature Importance', 'feature_all': 'Feature Importance (All)', 'tree': 'Decision Tree', 'residuals_interactive': 'Interactive Residuals'}, train_size=0.7, test_data=None, preprocess=True, imputation_type=simple, iterative_imputation_iters=5, categorical_features=None, categorical_imputation=constant, categorical_iterative_imputer=lightgbm, ordinal_features=None, high_cardinality_features=None, high_cardinality_method=frequency, numeric_features=None, numeric_imputation=mean, numeric_iterative_imputer=lightgbm, date_features=None, ignore_features=None, normalize=False, normalize_method=zscore, transformation=False, transformation_method=yeo-johnson, handle_unknown_categorical=True, unknown_categorical_method=least_frequent, pca=False, pca_method=linear, pca_components=None, ignore_low_variance=False, combine_rare_levels=False, rare_level_threshold=0.1, bin_numeric_features=None, remove_outliers=False, outliers_threshold=0.05, remove_multicollinearity=False, multicollinearity_threshold=0.9, remove_perfect_collinearity=True, create_clusters=False, cluster_iter=20, polynomial_features=False, polynomial_degree=2, trigonometry_features=False, polynomial_threshold=0.1, group_features=None, group_names=None, feature_selection=False, feature_selection_threshold=0.8, feature_selection_method=classic, feature_interaction=False, feature_ratio=False, interaction_threshold=0.01, fix_imbalance=False, fix_imbalance_method=None, transform_target=False, transform_target_method=box-cox, data_split_shuffle=True, data_split_stratify=False, fold_strategy=kfold, fold=10, fold_shuffle=False, fold_groups=None, n_jobs=-1, use_gpu=False, custom_pipeline=None, html=True, session_id=None, log_experiment=False, experiment_name=None, log_plots=False, log_profile=False, log_data=False, silent=False, verbose=True, profile=False, profile_kwargs=None, display=None)
2021-04-22 07:19:10,207:INFO:Checking environment
2021-04-22 07:19:10,207:INFO:python_version: 3.8.8
2021-04-22 07:19:10,207:INFO:python_build: ('tags/v3.8.8:024d805', 'Feb 19 2021 13:18:16')
2021-04-22 07:19:10,207:INFO:machine: AMD64
2021-04-22 07:19:10,207:INFO:platform: Windows-10-10.0.18362-SP0
2021-04-22 07:19:10,208:WARNING:cannot find psutil installation. memory not traceable. Install psutil using pip to enable memory logging.
2021-04-22 07:19:10,208:INFO:Checking libraries
2021-04-22 07:19:10,208:INFO:pd==1.2.4
2021-04-22 07:19:10,208:INFO:numpy==1.19.5
2021-04-22 07:19:10,208:INFO:sklearn==0.23.2
2021-04-22 07:19:10,208:INFO:lightgbm==3.2.1
2021-04-22 07:19:10,209:WARNING:catboost not found
2021-04-22 07:19:10,209:WARNING:xgboost not found
2021-04-22 07:19:10,465:INFO:mlflow==1.15.0
2021-04-22 07:19:10,465:INFO:Checking Exceptions
2021-04-22 07:19:10,465:INFO:Declaring global variables
2021-04-22 07:19:10,465:INFO:USI: 8a08
2021-04-22 07:19:10,465:INFO:pycaret_globals: {'USI', 'create_model_container', 'gpu_param', 'fold_param', 'target_param', 'fold_generator', 'seed', 'experiment__', 'transform_target_param', '_all_metrics', 'exp_name_log', 'prep_pipe', '_gpu_n_jobs_param', '_ml_usecase', 'imputation_regressor', '_all_models', 'stratify_param', 'transform_target_method_param', 'n_jobs_param', 'y_test', 'y', 'y_train', 'master_model_container', 'display_container', 'data_before_preprocess', '_all_models_internal', 'X_train', 'imputation_classifier', 'X', 'log_plots_param', 'pycaret_globals', 'fold_shuffle_param', 'fix_imbalance_method_param', 'iterative_imputation_iters_param', '_internal_pipeline', 'fold_groups_param', 'logging_param', '_available_plots', 'html_param', 'X_test', 'fix_imbalance_param'}
2021-04-22 07:19:10,465:INFO:Preparing display monitor
2021-04-22 07:19:10,465:INFO:Preparing display monitor
2021-04-22 07:19:10,470:INFO:Importing libraries
2021-04-22 07:19:10,470:INFO:Copying data for preprocessing
2021-04-22 07:19:10,472:INFO:Declaring preprocessing parameters
2021-04-22 07:19:10,472:INFO:Creating preprocessing pipeline
2021-04-22 07:19:10,487:INFO:Preprocessing pipeline created successfully
2021-04-22 07:19:10,487:ERROR:(Process Exit): setup has been interupted with user command 'quit'. setup must rerun.
2021-04-22 07:19:10,487:INFO:Creating global containers
2021-04-22 07:19:10,487:INFO:Internal pipeline: Pipeline(memory=None, steps=[('empty_step', 'passthrough')], verbose=False)
2021-04-22 07:23:28,466:WARNING:Couldn't import xgboost.XGBRegressor
2021-04-22 07:23:28,467:WARNING:Couldn't import catboost.CatBoostRegressor
2021-04-22 07:23:28,546:WARNING:Couldn't import xgboost.XGBRegressor
2021-04-22 07:23:28,546:WARNING:Couldn't import catboost.CatBoostRegressor
2021-04-22 07:23:28,546:INFO:Creating grid variables
2021-04-22 07:23:28,548:INFO:create_model_container: 0
2021-04-22 07:23:28,548:INFO:master_model_container: 0
2021-04-22 07:23:28,548:INFO:display_container: 1
2021-04-22 07:23:28,551:INFO:Pipeline(memory=None,
         steps=[('dtypes',
                 DataTypes_Auto_infer(categorical_features=[],
                                      display_types=True, features_todrop=[],
                                      id_columns=['Year', 'Survey year'],
                                      ml_usecase='regression',
                                      numerical_features=[], target='IWP IRI',
                                      time_features=[])),
                ('imputer',
                 Simple_Imputer(categorical_strategy='not_available',
                                fill_value_categorical=None,
                                fill_value_numerical=Non...
                ('scaling', 'passthrough'), ('P_transform', 'passthrough'),
                ('binn', 'passthrough'), ('rem_outliers', 'passthrough'),
                ('cluster_all', 'passthrough'),
                ('dummy', Dummify(target='IWP IRI')),
                ('fix_perfect', Remove_100(target='IWP IRI')),
                ('clean_names', Clean_Colum_Names()),
                ('feature_select', 'passthrough'), ('fix_multi', 'passthrough'),
                ('dfs', 'passthrough'), ('pca', 'passthrough')],
         verbose=False)
2021-04-22 07:23:28,551:INFO:setup() succesfully completed......................................
2021-04-22 07:23:28,600:INFO:Initializing compare_models()
2021-04-22 07:23:28,600:INFO:compare_models(include=None, fold=None, round=4, cross_validation=True, sort=R2, n_select=1, budget_time=None, turbo=True, errors=ignore, fit_kwargs=None, groups=None, verbose=True, display=None, exclude=None)
2021-04-22 07:23:28,600:INFO:Checking exceptions
2021-04-22 07:23:28,600:INFO:Preparing display monitor
2021-04-22 07:23:28,600:INFO:Preparing display monitor
2021-04-22 07:23:28,607:INFO:Initializing Linear Regression
2021-04-22 07:23:28,607:INFO:Total runtime is 1.657406489054362e-05 minutes
2021-04-22 07:23:28,608:INFO:SubProcess create_model() called ==================================
2021-04-22 07:23:28,608:INFO:Initializing create_model()
2021-04-22 07:23:28,608:INFO:create_model(estimator=lr, fold=KFold(n_splits=10, random_state=None, shuffle=False), round=4, cross_validation=True, predict=True, fit_kwargs={}, groups=None, refit=False, verbose=False, system=False, metrics=None, display=<pycaret.internal.Display.Display object at 0x0000025CF9FD29A0>, kwargs={})
2021-04-22 07:23:28,608:INFO:Checking exceptions
2021-04-22 07:23:28,608:INFO:Importing libraries
2021-04-22 07:23:28,609:INFO:Copying training dataset
2021-04-22 07:23:28,609:INFO:Defining folds
2021-04-22 07:23:28,609:INFO:Declaring metric variables
2021-04-22 07:23:28,610:INFO:Importing untrained model
2021-04-22 07:23:28,612:INFO:Linear Regression Imported succesfully
2021-04-22 07:23:28,615:INFO:Starting cross validation
2021-04-22 07:23:28,619:INFO:Cross validating with KFold(n_splits=10, random_state=None, shuffle=False), n_jobs=-1
2021-04-22 07:23:28,629:WARNING:create_model() for lr raised an exception or returned all 0.0, trying without fit_kwargs:
2021-04-22 07:23:28,634:WARNING:Traceback (most recent call last):
  File "D:\Passion Projects\PavementResearch\venv\lib\site-packages\joblib\parallel.py", line 820, in dispatch_one_batch
    tasks = self._ready_batches.get(block=False)
  File "C:\Users\lakit\AppData\Local\Programs\Python\Python38\lib\queue.py", line 167, in get
    raise Empty
_queue.Empty

During handling of the above exception, another exception occurred:

Traceback (most recent call last):
  File "D:\Passion Projects\PavementResearch\venv\lib\site-packages\pycaret\internal\tabular.py", line 2163, in compare_models
    model, model_fit_time = create_model_supervised(
  File "D:\Passion Projects\PavementResearch\venv\lib\site-packages\pycaret\internal\tabular.py", line 3112, in create_model_supervised
    scores = cross_validate(
  File "D:\Passion Projects\PavementResearch\venv\lib\site-packages\sklearn\utils\validation.py", line 72, in inner_f
    return f(**kwargs)
  File "D:\Passion Projects\PavementResearch\venv\lib\site-packages\sklearn\model_selection\_validation.py", line 242, in cross_validate
    scores = parallel(
  File "D:\Passion Projects\PavementResearch\venv\lib\site-packages\joblib\parallel.py", line 1041, in __call__
    if self.dispatch_one_batch(iterator):
  File "D:\Passion Projects\PavementResearch\venv\lib\site-packages\joblib\parallel.py", line 831, in dispatch_one_batch
    islice = list(itertools.islice(iterator, big_batch_size))
  File "D:\Passion Projects\PavementResearch\venv\lib\site-packages\sklearn\model_selection\_validation.py", line 242, in <genexpr>
    scores = parallel(
  File "D:\Passion Projects\PavementResearch\venv\lib\site-packages\sklearn\model_selection\_split.py", line 331, in split
    raise ValueError(
ValueError: Cannot have number of splits n_splits=10 greater than the number of samples: n_samples=4.

2021-04-22 07:23:28,634:INFO:Initializing create_model()
2021-04-22 07:23:28,634:INFO:create_model(estimator=lr, fold=KFold(n_splits=10, random_state=None, shuffle=False), round=4, cross_validation=True, predict=True, fit_kwargs=None, groups=None, refit=False, verbose=False, system=False, metrics=None, display=<pycaret.internal.Display.Display object at 0x0000025CF9FD29A0>, kwargs={})
2021-04-22 07:23:28,635:INFO:Checking exceptions
2021-04-22 07:23:28,635:INFO:Importing libraries
2021-04-22 07:23:28,635:INFO:Copying training dataset
2021-04-22 07:23:28,635:INFO:Defining folds
2021-04-22 07:23:28,635:INFO:Declaring metric variables
2021-04-22 07:23:28,637:INFO:Importing untrained model
2021-04-22 07:23:28,638:INFO:Linear Regression Imported succesfully
2021-04-22 07:23:28,642:INFO:Starting cross validation
2021-04-22 07:23:28,642:INFO:Cross validating with KFold(n_splits=10, random_state=None, shuffle=False), n_jobs=-1
2021-04-22 07:23:28,643:ERROR:create_model() for lr raised an exception:
2021-04-22 07:23:28,644:ERROR:Traceback (most recent call last):
  File "D:\Passion Projects\PavementResearch\venv\lib\site-packages\joblib\parallel.py", line 820, in dispatch_one_batch
    tasks = self._ready_batches.get(block=False)
  File "C:\Users\lakit\AppData\Local\Programs\Python\Python38\lib\queue.py", line 167, in get
    raise Empty
_queue.Empty

During handling of the above exception, another exception occurred:

Traceback (most recent call last):
  File "D:\Passion Projects\PavementResearch\venv\lib\site-packages\pycaret\internal\tabular.py", line 2163, in compare_models
    model, model_fit_time = create_model_supervised(
  File "D:\Passion Projects\PavementResearch\venv\lib\site-packages\pycaret\internal\tabular.py", line 3112, in create_model_supervised
    scores = cross_validate(
  File "D:\Passion Projects\PavementResearch\venv\lib\site-packages\sklearn\utils\validation.py", line 72, in inner_f
    return f(**kwargs)
  File "D:\Passion Projects\PavementResearch\venv\lib\site-packages\sklearn\model_selection\_validation.py", line 242, in cross_validate
    scores = parallel(
  File "D:\Passion Projects\PavementResearch\venv\lib\site-packages\joblib\parallel.py", line 1041, in __call__
    if self.dispatch_one_batch(iterator):
  File "D:\Passion Projects\PavementResearch\venv\lib\site-packages\joblib\parallel.py", line 831, in dispatch_one_batch
    islice = list(itertools.islice(iterator, big_batch_size))
  File "D:\Passion Projects\PavementResearch\venv\lib\site-packages\sklearn\model_selection\_validation.py", line 242, in <genexpr>
    scores = parallel(
  File "D:\Passion Projects\PavementResearch\venv\lib\site-packages\sklearn\model_selection\_split.py", line 331, in split
    raise ValueError(
ValueError: Cannot have number of splits n_splits=10 greater than the number of samples: n_samples=4.

During handling of the above exception, another exception occurred:

Traceback (most recent call last):
  File "D:\Passion Projects\PavementResearch\venv\lib\site-packages\joblib\parallel.py", line 820, in dispatch_one_batch
    tasks = self._ready_batches.get(block=False)
  File "C:\Users\lakit\AppData\Local\Programs\Python\Python38\lib\queue.py", line 167, in get
    raise Empty
_queue.Empty

During handling of the above exception, another exception occurred:

Traceback (most recent call last):
  File "D:\Passion Projects\PavementResearch\venv\lib\site-packages\pycaret\internal\tabular.py", line 2183, in compare_models
    model, model_fit_time = create_model_supervised(
  File "D:\Passion Projects\PavementResearch\venv\lib\site-packages\pycaret\internal\tabular.py", line 3112, in create_model_supervised
    scores = cross_validate(
  File "D:\Passion Projects\PavementResearch\venv\lib\site-packages\sklearn\utils\validation.py", line 72, in inner_f
    return f(**kwargs)
  File "D:\Passion Projects\PavementResearch\venv\lib\site-packages\sklearn\model_selection\_validation.py", line 242, in cross_validate
    scores = parallel(
  File "D:\Passion Projects\PavementResearch\venv\lib\site-packages\joblib\parallel.py", line 1041, in __call__
    if self.dispatch_one_batch(iterator):
  File "D:\Passion Projects\PavementResearch\venv\lib\site-packages\joblib\parallel.py", line 831, in dispatch_one_batch
    islice = list(itertools.islice(iterator, big_batch_size))
  File "D:\Passion Projects\PavementResearch\venv\lib\site-packages\sklearn\model_selection\_validation.py", line 242, in <genexpr>
    scores = parallel(
  File "D:\Passion Projects\PavementResearch\venv\lib\site-packages\sklearn\model_selection\_split.py", line 331, in split
    raise ValueError(
ValueError: Cannot have number of splits n_splits=10 greater than the number of samples: n_samples=4.

2021-04-22 07:23:28,644:INFO:Initializing Lasso Regression
2021-04-22 07:23:28,644:INFO:Total runtime is 0.0006332119305928549 minutes
2021-04-22 07:23:28,645:INFO:SubProcess create_model() called ==================================
2021-04-22 07:23:28,646:INFO:Initializing create_model()
2021-04-22 07:23:28,646:INFO:create_model(estimator=lasso, fold=KFold(n_splits=10, random_state=None, shuffle=False), round=4, cross_validation=True, predict=True, fit_kwargs={}, groups=None, refit=False, verbose=False, system=False, metrics=None, display=<pycaret.internal.Display.Display object at 0x0000025CF9FD29A0>, kwargs={})
2021-04-22 07:23:28,646:INFO:Checking exceptions
2021-04-22 07:23:28,646:INFO:Importing libraries
2021-04-22 07:23:28,646:INFO:Copying training dataset
2021-04-22 07:23:28,646:INFO:Defining folds
2021-04-22 07:23:28,646:INFO:Declaring metric variables
2021-04-22 07:23:28,647:INFO:Importing untrained model
2021-04-22 07:23:28,649:INFO:Lasso Regression Imported succesfully
2021-04-22 07:23:28,652:INFO:Starting cross validation
2021-04-22 07:23:28,653:INFO:Cross validating with KFold(n_splits=10, random_state=None, shuffle=False), n_jobs=-1
2021-04-22 07:23:28,653:WARNING:create_model() for lasso raised an exception or returned all 0.0, trying without fit_kwargs:
2021-04-22 07:23:28,654:WARNING:Traceback (most recent call last):
  File "D:\Passion Projects\PavementResearch\venv\lib\site-packages\joblib\parallel.py", line 820, in dispatch_one_batch
    tasks = self._ready_batches.get(block=False)
  File "C:\Users\lakit\AppData\Local\Programs\Python\Python38\lib\queue.py", line 167, in get
    raise Empty
_queue.Empty

During handling of the above exception, another exception occurred:

Traceback (most recent call last):
  File "D:\Passion Projects\PavementResearch\venv\lib\site-packages\pycaret\internal\tabular.py", line 2163, in compare_models
    model, model_fit_time = create_model_supervised(
  File "D:\Passion Projects\PavementResearch\venv\lib\site-packages\pycaret\internal\tabular.py", line 3112, in create_model_supervised
    scores = cross_validate(
  File "D:\Passion Projects\PavementResearch\venv\lib\site-packages\sklearn\utils\validation.py", line 72, in inner_f
    return f(**kwargs)
  File "D:\Passion Projects\PavementResearch\venv\lib\site-packages\sklearn\model_selection\_validation.py", line 242, in cross_validate
    scores = parallel(
  File "D:\Passion Projects\PavementResearch\venv\lib\site-packages\joblib\parallel.py", line 1041, in __call__
    if self.dispatch_one_batch(iterator):
  File "D:\Passion Projects\PavementResearch\venv\lib\site-packages\joblib\parallel.py", line 831, in dispatch_one_batch
    islice = list(itertools.islice(iterator, big_batch_size))
  File "D:\Passion Projects\PavementResearch\venv\lib\site-packages\sklearn\model_selection\_validation.py", line 242, in <genexpr>
    scores = parallel(
  File "D:\Passion Projects\PavementResearch\venv\lib\site-packages\sklearn\model_selection\_split.py", line 331, in split
    raise ValueError(
ValueError: Cannot have number of splits n_splits=10 greater than the number of samples: n_samples=4.

2021-04-22 07:23:28,654:INFO:Initializing create_model()
2021-04-22 07:23:28,654:INFO:create_model(estimator=lasso, fold=KFold(n_splits=10, random_state=None, shuffle=False), round=4, cross_validation=True, predict=True, fit_kwargs=None, groups=None, refit=False, verbose=False, system=False, metrics=None, display=<pycaret.internal.Display.Display object at 0x0000025CF9FD29A0>, kwargs={})
2021-04-22 07:23:28,654:INFO:Checking exceptions
2021-04-22 07:23:28,654:INFO:Importing libraries
2021-04-22 07:23:28,654:INFO:Copying training dataset
2021-04-22 07:23:28,654:INFO:Defining folds
2021-04-22 07:23:28,654:INFO:Declaring metric variables
2021-04-22 07:23:28,656:INFO:Importing untrained model
2021-04-22 07:23:28,658:INFO:Lasso Regression Imported succesfully
2021-04-22 07:23:28,661:INFO:Starting cross validation
2021-04-22 07:23:28,661:INFO:Cross validating with KFold(n_splits=10, random_state=None, shuffle=False), n_jobs=-1
2021-04-22 07:23:28,662:ERROR:create_model() for lasso raised an exception:
2021-04-22 07:23:28,662:ERROR:Traceback (most recent call last):
  File "D:\Passion Projects\PavementResearch\venv\lib\site-packages\joblib\parallel.py", line 820, in dispatch_one_batch
    tasks = self._ready_batches.get(block=False)
  File "C:\Users\lakit\AppData\Local\Programs\Python\Python38\lib\queue.py", line 167, in get
    raise Empty
_queue.Empty

During handling of the above exception, another exception occurred:

Traceback (most recent call last):
  File "D:\Passion Projects\PavementResearch\venv\lib\site-packages\pycaret\internal\tabular.py", line 2163, in compare_models
    model, model_fit_time = create_model_supervised(
  File "D:\Passion Projects\PavementResearch\venv\lib\site-packages\pycaret\internal\tabular.py", line 3112, in create_model_supervised
    scores = cross_validate(
  File "D:\Passion Projects\PavementResearch\venv\lib\site-packages\sklearn\utils\validation.py", line 72, in inner_f
    return f(**kwargs)
  File "D:\Passion Projects\PavementResearch\venv\lib\site-packages\sklearn\model_selection\_validation.py", line 242, in cross_validate
    scores = parallel(
  File "D:\Passion Projects\PavementResearch\venv\lib\site-packages\joblib\parallel.py", line 1041, in __call__
    if self.dispatch_one_batch(iterator):
  File "D:\Passion Projects\PavementResearch\venv\lib\site-packages\joblib\parallel.py", line 831, in dispatch_one_batch
    islice = list(itertools.islice(iterator, big_batch_size))
  File "D:\Passion Projects\PavementResearch\venv\lib\site-packages\sklearn\model_selection\_validation.py", line 242, in <genexpr>
    scores = parallel(
  File "D:\Passion Projects\PavementResearch\venv\lib\site-packages\sklearn\model_selection\_split.py", line 331, in split
    raise ValueError(
ValueError: Cannot have number of splits n_splits=10 greater than the number of samples: n_samples=4.

During handling of the above exception, another exception occurred:

Traceback (most recent call last):
  File "D:\Passion Projects\PavementResearch\venv\lib\site-packages\joblib\parallel.py", line 820, in dispatch_one_batch
    tasks = self._ready_batches.get(block=False)
  File "C:\Users\lakit\AppData\Local\Programs\Python\Python38\lib\queue.py", line 167, in get
    raise Empty
_queue.Empty

During handling of the above exception, another exception occurred:

Traceback (most recent call last):
  File "D:\Passion Projects\PavementResearch\venv\lib\site-packages\pycaret\internal\tabular.py", line 2183, in compare_models
    model, model_fit_time = create_model_supervised(
  File "D:\Passion Projects\PavementResearch\venv\lib\site-packages\pycaret\internal\tabular.py", line 3112, in create_model_supervised
    scores = cross_validate(
  File "D:\Passion Projects\PavementResearch\venv\lib\site-packages\sklearn\utils\validation.py", line 72, in inner_f
    return f(**kwargs)
  File "D:\Passion Projects\PavementResearch\venv\lib\site-packages\sklearn\model_selection\_validation.py", line 242, in cross_validate
    scores = parallel(
  File "D:\Passion Projects\PavementResearch\venv\lib\site-packages\joblib\parallel.py", line 1041, in __call__
    if self.dispatch_one_batch(iterator):
  File "D:\Passion Projects\PavementResearch\venv\lib\site-packages\joblib\parallel.py", line 831, in dispatch_one_batch
    islice = list(itertools.islice(iterator, big_batch_size))
  File "D:\Passion Projects\PavementResearch\venv\lib\site-packages\sklearn\model_selection\_validation.py", line 242, in <genexpr>
    scores = parallel(
  File "D:\Passion Projects\PavementResearch\venv\lib\site-packages\sklearn\model_selection\_split.py", line 331, in split
    raise ValueError(
ValueError: Cannot have number of splits n_splits=10 greater than the number of samples: n_samples=4.

2021-04-22 07:23:28,663:INFO:Initializing Ridge Regression
2021-04-22 07:23:28,663:INFO:Total runtime is 0.0009494304656982423 minutes
2021-04-22 07:23:28,664:INFO:SubProcess create_model() called ==================================
2021-04-22 07:23:28,664:INFO:Initializing create_model()
2021-04-22 07:23:28,664:INFO:create_model(estimator=ridge, fold=KFold(n_splits=10, random_state=None, shuffle=False), round=4, cross_validation=True, predict=True, fit_kwargs={}, groups=None, refit=False, verbose=False, system=False, metrics=None, display=<pycaret.internal.Display.Display object at 0x0000025CF9FD29A0>, kwargs={})
2021-04-22 07:23:28,664:INFO:Checking exceptions
2021-04-22 07:23:28,664:INFO:Importing libraries
2021-04-22 07:23:28,665:INFO:Copying training dataset
2021-04-22 07:23:28,665:INFO:Defining folds
2021-04-22 07:23:28,665:INFO:Declaring metric variables
2021-04-22 07:23:28,666:INFO:Importing untrained model
2021-04-22 07:23:28,668:INFO:Ridge Regression Imported succesfully
2021-04-22 07:23:28,671:INFO:Starting cross validation
2021-04-22 07:23:28,671:INFO:Cross validating with KFold(n_splits=10, random_state=None, shuffle=False), n_jobs=-1
2021-04-22 07:23:28,672:WARNING:create_model() for ridge raised an exception or returned all 0.0, trying without fit_kwargs:
2021-04-22 07:23:28,672:WARNING:Traceback (most recent call last):
  File "D:\Passion Projects\PavementResearch\venv\lib\site-packages\joblib\parallel.py", line 820, in dispatch_one_batch
    tasks = self._ready_batches.get(block=False)
  File "C:\Users\lakit\AppData\Local\Programs\Python\Python38\lib\queue.py", line 167, in get
    raise Empty
_queue.Empty

During handling of the above exception, another exception occurred:

Traceback (most recent call last):
  File "D:\Passion Projects\PavementResearch\venv\lib\site-packages\pycaret\internal\tabular.py", line 2163, in compare_models
    model, model_fit_time = create_model_supervised(
  File "D:\Passion Projects\PavementResearch\venv\lib\site-packages\pycaret\internal\tabular.py", line 3112, in create_model_supervised
    scores = cross_validate(
  File "D:\Passion Projects\PavementResearch\venv\lib\site-packages\sklearn\utils\validation.py", line 72, in inner_f
    return f(**kwargs)
  File "D:\Passion Projects\PavementResearch\venv\lib\site-packages\sklearn\model_selection\_validation.py", line 242, in cross_validate
    scores = parallel(
  File "D:\Passion Projects\PavementResearch\venv\lib\site-packages\joblib\parallel.py", line 1041, in __call__
    if self.dispatch_one_batch(iterator):
  File "D:\Passion Projects\PavementResearch\venv\lib\site-packages\joblib\parallel.py", line 831, in dispatch_one_batch
    islice = list(itertools.islice(iterator, big_batch_size))
  File "D:\Passion Projects\PavementResearch\venv\lib\site-packages\sklearn\model_selection\_validation.py", line 242, in <genexpr>
    scores = parallel(
  File "D:\Passion Projects\PavementResearch\venv\lib\site-packages\sklearn\model_selection\_split.py", line 331, in split
    raise ValueError(
ValueError: Cannot have number of splits n_splits=10 greater than the number of samples: n_samples=4.

2021-04-22 07:23:28,673:INFO:Initializing create_model()
2021-04-22 07:23:28,673:INFO:create_model(estimator=ridge, fold=KFold(n_splits=10, random_state=None, shuffle=False), round=4, cross_validation=True, predict=True, fit_kwargs=None, groups=None, refit=False, verbose=False, system=False, metrics=None, display=<pycaret.internal.Display.Display object at 0x0000025CF9FD29A0>, kwargs={})
2021-04-22 07:23:28,673:INFO:Checking exceptions
2021-04-22 07:23:28,673:INFO:Importing libraries
2021-04-22 07:23:28,673:INFO:Copying training dataset
2021-04-22 07:23:28,673:INFO:Defining folds
2021-04-22 07:23:28,673:INFO:Declaring metric variables
2021-04-22 07:23:28,675:INFO:Importing untrained model
2021-04-22 07:23:28,676:INFO:Ridge Regression Imported succesfully
2021-04-22 07:23:28,679:INFO:Starting cross validation
2021-04-22 07:23:28,680:INFO:Cross validating with KFold(n_splits=10, random_state=None, shuffle=False), n_jobs=-1
2021-04-22 07:23:28,680:ERROR:create_model() for ridge raised an exception:
2021-04-22 07:23:28,681:ERROR:Traceback (most recent call last):
  File "D:\Passion Projects\PavementResearch\venv\lib\site-packages\joblib\parallel.py", line 820, in dispatch_one_batch
    tasks = self._ready_batches.get(block=False)
  File "C:\Users\lakit\AppData\Local\Programs\Python\Python38\lib\queue.py", line 167, in get
    raise Empty
_queue.Empty

During handling of the above exception, another exception occurred:

Traceback (most recent call last):
  File "D:\Passion Projects\PavementResearch\venv\lib\site-packages\pycaret\internal\tabular.py", line 2163, in compare_models
    model, model_fit_time = create_model_supervised(
  File "D:\Passion Projects\PavementResearch\venv\lib\site-packages\pycaret\internal\tabular.py", line 3112, in create_model_supervised
    scores = cross_validate(
  File "D:\Passion Projects\PavementResearch\venv\lib\site-packages\sklearn\utils\validation.py", line 72, in inner_f
    return f(**kwargs)
  File "D:\Passion Projects\PavementResearch\venv\lib\site-packages\sklearn\model_selection\_validation.py", line 242, in cross_validate
    scores = parallel(
  File "D:\Passion Projects\PavementResearch\venv\lib\site-packages\joblib\parallel.py", line 1041, in __call__
    if self.dispatch_one_batch(iterator):
  File "D:\Passion Projects\PavementResearch\venv\lib\site-packages\joblib\parallel.py", line 831, in dispatch_one_batch
    islice = list(itertools.islice(iterator, big_batch_size))
  File "D:\Passion Projects\PavementResearch\venv\lib\site-packages\sklearn\model_selection\_validation.py", line 242, in <genexpr>
    scores = parallel(
  File "D:\Passion Projects\PavementResearch\venv\lib\site-packages\sklearn\model_selection\_split.py", line 331, in split
    raise ValueError(
ValueError: Cannot have number of splits n_splits=10 greater than the number of samples: n_samples=4.

During handling of the above exception, another exception occurred:

Traceback (most recent call last):
  File "D:\Passion Projects\PavementResearch\venv\lib\site-packages\joblib\parallel.py", line 820, in dispatch_one_batch
    tasks = self._ready_batches.get(block=False)
  File "C:\Users\lakit\AppData\Local\Programs\Python\Python38\lib\queue.py", line 167, in get
    raise Empty
_queue.Empty

During handling of the above exception, another exception occurred:

Traceback (most recent call last):
  File "D:\Passion Projects\PavementResearch\venv\lib\site-packages\pycaret\internal\tabular.py", line 2183, in compare_models
    model, model_fit_time = create_model_supervised(
  File "D:\Passion Projects\PavementResearch\venv\lib\site-packages\pycaret\internal\tabular.py", line 3112, in create_model_supervised
    scores = cross_validate(
  File "D:\Passion Projects\PavementResearch\venv\lib\site-packages\sklearn\utils\validation.py", line 72, in inner_f
    return f(**kwargs)
  File "D:\Passion Projects\PavementResearch\venv\lib\site-packages\sklearn\model_selection\_validation.py", line 242, in cross_validate
    scores = parallel(
  File "D:\Passion Projects\PavementResearch\venv\lib\site-packages\joblib\parallel.py", line 1041, in __call__
    if self.dispatch_one_batch(iterator):
  File "D:\Passion Projects\PavementResearch\venv\lib\site-packages\joblib\parallel.py", line 831, in dispatch_one_batch
    islice = list(itertools.islice(iterator, big_batch_size))
  File "D:\Passion Projects\PavementResearch\venv\lib\site-packages\sklearn\model_selection\_validation.py", line 242, in <genexpr>
    scores = parallel(
  File "D:\Passion Projects\PavementResearch\venv\lib\site-packages\sklearn\model_selection\_split.py", line 331, in split
    raise ValueError(
ValueError: Cannot have number of splits n_splits=10 greater than the number of samples: n_samples=4.

2021-04-22 07:23:28,681:INFO:Initializing Elastic Net
2021-04-22 07:23:28,681:INFO:Total runtime is 0.0012494285901387533 minutes
2021-04-22 07:23:28,683:INFO:SubProcess create_model() called ==================================
2021-04-22 07:23:28,683:INFO:Initializing create_model()
2021-04-22 07:23:28,683:INFO:create_model(estimator=en, fold=KFold(n_splits=10, random_state=None, shuffle=False), round=4, cross_validation=True, predict=True, fit_kwargs={}, groups=None, refit=False, verbose=False, system=False, metrics=None, display=<pycaret.internal.Display.Display object at 0x0000025CF9FD29A0>, kwargs={})
2021-04-22 07:23:28,683:INFO:Checking exceptions
2021-04-22 07:23:28,683:INFO:Importing libraries
2021-04-22 07:23:28,683:INFO:Copying training dataset
2021-04-22 07:23:28,683:INFO:Defining folds
2021-04-22 07:23:28,683:INFO:Declaring metric variables
2021-04-22 07:23:28,685:INFO:Importing untrained model
2021-04-22 07:23:28,687:INFO:Elastic Net Imported succesfully
2021-04-22 07:23:28,690:INFO:Starting cross validation
2021-04-22 07:23:28,690:INFO:Cross validating with KFold(n_splits=10, random_state=None, shuffle=False), n_jobs=-1
2021-04-22 07:23:28,691:WARNING:create_model() for en raised an exception or returned all 0.0, trying without fit_kwargs:
2021-04-22 07:23:28,691:WARNING:Traceback (most recent call last):
  File "D:\Passion Projects\PavementResearch\venv\lib\site-packages\joblib\parallel.py", line 820, in dispatch_one_batch
    tasks = self._ready_batches.get(block=False)
  File "C:\Users\lakit\AppData\Local\Programs\Python\Python38\lib\queue.py", line 167, in get
    raise Empty
_queue.Empty

During handling of the above exception, another exception occurred:

Traceback (most recent call last):
  File "D:\Passion Projects\PavementResearch\venv\lib\site-packages\pycaret\internal\tabular.py", line 2163, in compare_models
    model, model_fit_time = create_model_supervised(
  File "D:\Passion Projects\PavementResearch\venv\lib\site-packages\pycaret\internal\tabular.py", line 3112, in create_model_supervised
    scores = cross_validate(
  File "D:\Passion Projects\PavementResearch\venv\lib\site-packages\sklearn\utils\validation.py", line 72, in inner_f
    return f(**kwargs)
  File "D:\Passion Projects\PavementResearch\venv\lib\site-packages\sklearn\model_selection\_validation.py", line 242, in cross_validate
    scores = parallel(
  File "D:\Passion Projects\PavementResearch\venv\lib\site-packages\joblib\parallel.py", line 1041, in __call__
    if self.dispatch_one_batch(iterator):
  File "D:\Passion Projects\PavementResearch\venv\lib\site-packages\joblib\parallel.py", line 831, in dispatch_one_batch
    islice = list(itertools.islice(iterator, big_batch_size))
  File "D:\Passion Projects\PavementResearch\venv\lib\site-packages\sklearn\model_selection\_validation.py", line 242, in <genexpr>
    scores = parallel(
  File "D:\Passion Projects\PavementResearch\venv\lib\site-packages\sklearn\model_selection\_split.py", line 331, in split
    raise ValueError(
ValueError: Cannot have number of splits n_splits=10 greater than the number of samples: n_samples=4.

2021-04-22 07:23:28,691:INFO:Initializing create_model()
2021-04-22 07:23:28,691:INFO:create_model(estimator=en, fold=KFold(n_splits=10, random_state=None, shuffle=False), round=4, cross_validation=True, predict=True, fit_kwargs=None, groups=None, refit=False, verbose=False, system=False, metrics=None, display=<pycaret.internal.Display.Display object at 0x0000025CF9FD29A0>, kwargs={})
2021-04-22 07:23:28,691:INFO:Checking exceptions
2021-04-22 07:23:28,691:INFO:Importing libraries
2021-04-22 07:23:28,691:INFO:Copying training dataset
2021-04-22 07:23:28,692:INFO:Defining folds
2021-04-22 07:23:28,692:INFO:Declaring metric variables
2021-04-22 07:23:28,693:INFO:Importing untrained model
2021-04-22 07:23:28,695:INFO:Elastic Net Imported succesfully
2021-04-22 07:23:28,698:INFO:Starting cross validation
2021-04-22 07:23:28,698:INFO:Cross validating with KFold(n_splits=10, random_state=None, shuffle=False), n_jobs=-1
2021-04-22 07:23:28,699:ERROR:create_model() for en raised an exception:
2021-04-22 07:23:28,700:ERROR:Traceback (most recent call last):
  File "D:\Passion Projects\PavementResearch\venv\lib\site-packages\joblib\parallel.py", line 820, in dispatch_one_batch
    tasks = self._ready_batches.get(block=False)
  File "C:\Users\lakit\AppData\Local\Programs\Python\Python38\lib\queue.py", line 167, in get
    raise Empty
_queue.Empty

During handling of the above exception, another exception occurred:

Traceback (most recent call last):
  File "D:\Passion Projects\PavementResearch\venv\lib\site-packages\pycaret\internal\tabular.py", line 2163, in compare_models
    model, model_fit_time = create_model_supervised(
  File "D:\Passion Projects\PavementResearch\venv\lib\site-packages\pycaret\internal\tabular.py", line 3112, in create_model_supervised
    scores = cross_validate(
  File "D:\Passion Projects\PavementResearch\venv\lib\site-packages\sklearn\utils\validation.py", line 72, in inner_f
    return f(**kwargs)
  File "D:\Passion Projects\PavementResearch\venv\lib\site-packages\sklearn\model_selection\_validation.py", line 242, in cross_validate
    scores = parallel(
  File "D:\Passion Projects\PavementResearch\venv\lib\site-packages\joblib\parallel.py", line 1041, in __call__
    if self.dispatch_one_batch(iterator):
  File "D:\Passion Projects\PavementResearch\venv\lib\site-packages\joblib\parallel.py", line 831, in dispatch_one_batch
    islice = list(itertools.islice(iterator, big_batch_size))
  File "D:\Passion Projects\PavementResearch\venv\lib\site-packages\sklearn\model_selection\_validation.py", line 242, in <genexpr>
    scores = parallel(
  File "D:\Passion Projects\PavementResearch\venv\lib\site-packages\sklearn\model_selection\_split.py", line 331, in split
    raise ValueError(
ValueError: Cannot have number of splits n_splits=10 greater than the number of samples: n_samples=4.

During handling of the above exception, another exception occurred:

Traceback (most recent call last):
  File "D:\Passion Projects\PavementResearch\venv\lib\site-packages\joblib\parallel.py", line 820, in dispatch_one_batch
    tasks = self._ready_batches.get(block=False)
  File "C:\Users\lakit\AppData\Local\Programs\Python\Python38\lib\queue.py", line 167, in get
    raise Empty
_queue.Empty

During handling of the above exception, another exception occurred:

Traceback (most recent call last):
  File "D:\Passion Projects\PavementResearch\venv\lib\site-packages\pycaret\internal\tabular.py", line 2183, in compare_models
    model, model_fit_time = create_model_supervised(
  File "D:\Passion Projects\PavementResearch\venv\lib\site-packages\pycaret\internal\tabular.py", line 3112, in create_model_supervised
    scores = cross_validate(
  File "D:\Passion Projects\PavementResearch\venv\lib\site-packages\sklearn\utils\validation.py", line 72, in inner_f
    return f(**kwargs)
  File "D:\Passion Projects\PavementResearch\venv\lib\site-packages\sklearn\model_selection\_validation.py", line 242, in cross_validate
    scores = parallel(
  File "D:\Passion Projects\PavementResearch\venv\lib\site-packages\joblib\parallel.py", line 1041, in __call__
    if self.dispatch_one_batch(iterator):
  File "D:\Passion Projects\PavementResearch\venv\lib\site-packages\joblib\parallel.py", line 831, in dispatch_one_batch
    islice = list(itertools.islice(iterator, big_batch_size))
  File "D:\Passion Projects\PavementResearch\venv\lib\site-packages\sklearn\model_selection\_validation.py", line 242, in <genexpr>
    scores = parallel(
  File "D:\Passion Projects\PavementResearch\venv\lib\site-packages\sklearn\model_selection\_split.py", line 331, in split
    raise ValueError(
ValueError: Cannot have number of splits n_splits=10 greater than the number of samples: n_samples=4.

2021-04-22 07:23:28,700:INFO:Initializing Least Angle Regression
2021-04-22 07:23:28,700:INFO:Total runtime is 0.0015665451685587565 minutes
2021-04-22 07:23:28,702:INFO:SubProcess create_model() called ==================================
2021-04-22 07:23:28,702:INFO:Initializing create_model()
2021-04-22 07:23:28,702:INFO:create_model(estimator=lar, fold=KFold(n_splits=10, random_state=None, shuffle=False), round=4, cross_validation=True, predict=True, fit_kwargs={}, groups=None, refit=False, verbose=False, system=False, metrics=None, display=<pycaret.internal.Display.Display object at 0x0000025CF9FD29A0>, kwargs={})
2021-04-22 07:23:28,702:INFO:Checking exceptions
2021-04-22 07:23:28,702:INFO:Importing libraries
2021-04-22 07:23:28,702:INFO:Copying training dataset
2021-04-22 07:23:28,702:INFO:Defining folds
2021-04-22 07:23:28,702:INFO:Declaring metric variables
2021-04-22 07:23:28,704:INFO:Importing untrained model
2021-04-22 07:23:28,705:INFO:Least Angle Regression Imported succesfully
2021-04-22 07:23:28,709:INFO:Starting cross validation
2021-04-22 07:23:28,709:INFO:Cross validating with KFold(n_splits=10, random_state=None, shuffle=False), n_jobs=-1
2021-04-22 07:23:28,709:WARNING:create_model() for lar raised an exception or returned all 0.0, trying without fit_kwargs:
2021-04-22 07:23:28,710:WARNING:Traceback (most recent call last):
  File "D:\Passion Projects\PavementResearch\venv\lib\site-packages\joblib\parallel.py", line 820, in dispatch_one_batch
    tasks = self._ready_batches.get(block=False)
  File "C:\Users\lakit\AppData\Local\Programs\Python\Python38\lib\queue.py", line 167, in get
    raise Empty
_queue.Empty

During handling of the above exception, another exception occurred:

Traceback (most recent call last):
  File "D:\Passion Projects\PavementResearch\venv\lib\site-packages\pycaret\internal\tabular.py", line 2163, in compare_models
    model, model_fit_time = create_model_supervised(
  File "D:\Passion Projects\PavementResearch\venv\lib\site-packages\pycaret\internal\tabular.py", line 3112, in create_model_supervised
    scores = cross_validate(
  File "D:\Passion Projects\PavementResearch\venv\lib\site-packages\sklearn\utils\validation.py", line 72, in inner_f
    return f(**kwargs)
  File "D:\Passion Projects\PavementResearch\venv\lib\site-packages\sklearn\model_selection\_validation.py", line 242, in cross_validate
    scores = parallel(
  File "D:\Passion Projects\PavementResearch\venv\lib\site-packages\joblib\parallel.py", line 1041, in __call__
    if self.dispatch_one_batch(iterator):
  File "D:\Passion Projects\PavementResearch\venv\lib\site-packages\joblib\parallel.py", line 831, in dispatch_one_batch
    islice = list(itertools.islice(iterator, big_batch_size))
  File "D:\Passion Projects\PavementResearch\venv\lib\site-packages\sklearn\model_selection\_validation.py", line 242, in <genexpr>
    scores = parallel(
  File "D:\Passion Projects\PavementResearch\venv\lib\site-packages\sklearn\model_selection\_split.py", line 331, in split
    raise ValueError(
ValueError: Cannot have number of splits n_splits=10 greater than the number of samples: n_samples=4.

2021-04-22 07:23:28,710:INFO:Initializing create_model()
2021-04-22 07:23:28,710:INFO:create_model(estimator=lar, fold=KFold(n_splits=10, random_state=None, shuffle=False), round=4, cross_validation=True, predict=True, fit_kwargs=None, groups=None, refit=False, verbose=False, system=False, metrics=None, display=<pycaret.internal.Display.Display object at 0x0000025CF9FD29A0>, kwargs={})
2021-04-22 07:23:28,710:INFO:Checking exceptions
2021-04-22 07:23:28,710:INFO:Importing libraries
2021-04-22 07:23:28,710:INFO:Copying training dataset
2021-04-22 07:23:28,710:INFO:Defining folds
2021-04-22 07:23:28,710:INFO:Declaring metric variables
2021-04-22 07:23:28,713:INFO:Importing untrained model
2021-04-22 07:23:28,714:INFO:Least Angle Regression Imported succesfully
2021-04-22 07:23:28,717:INFO:Starting cross validation
2021-04-22 07:23:28,717:INFO:Cross validating with KFold(n_splits=10, random_state=None, shuffle=False), n_jobs=-1
2021-04-22 07:23:28,718:ERROR:create_model() for lar raised an exception:
2021-04-22 07:23:28,719:ERROR:Traceback (most recent call last):
  File "D:\Passion Projects\PavementResearch\venv\lib\site-packages\joblib\parallel.py", line 820, in dispatch_one_batch
    tasks = self._ready_batches.get(block=False)
  File "C:\Users\lakit\AppData\Local\Programs\Python\Python38\lib\queue.py", line 167, in get
    raise Empty
_queue.Empty

During handling of the above exception, another exception occurred:

Traceback (most recent call last):
  File "D:\Passion Projects\PavementResearch\venv\lib\site-packages\pycaret\internal\tabular.py", line 2163, in compare_models
    model, model_fit_time = create_model_supervised(
  File "D:\Passion Projects\PavementResearch\venv\lib\site-packages\pycaret\internal\tabular.py", line 3112, in create_model_supervised
    scores = cross_validate(
  File "D:\Passion Projects\PavementResearch\venv\lib\site-packages\sklearn\utils\validation.py", line 72, in inner_f
    return f(**kwargs)
  File "D:\Passion Projects\PavementResearch\venv\lib\site-packages\sklearn\model_selection\_validation.py", line 242, in cross_validate
    scores = parallel(
  File "D:\Passion Projects\PavementResearch\venv\lib\site-packages\joblib\parallel.py", line 1041, in __call__
    if self.dispatch_one_batch(iterator):
  File "D:\Passion Projects\PavementResearch\venv\lib\site-packages\joblib\parallel.py", line 831, in dispatch_one_batch
    islice = list(itertools.islice(iterator, big_batch_size))
  File "D:\Passion Projects\PavementResearch\venv\lib\site-packages\sklearn\model_selection\_validation.py", line 242, in <genexpr>
    scores = parallel(
  File "D:\Passion Projects\PavementResearch\venv\lib\site-packages\sklearn\model_selection\_split.py", line 331, in split
    raise ValueError(
ValueError: Cannot have number of splits n_splits=10 greater than the number of samples: n_samples=4.

During handling of the above exception, another exception occurred:

Traceback (most recent call last):
  File "D:\Passion Projects\PavementResearch\venv\lib\site-packages\joblib\parallel.py", line 820, in dispatch_one_batch
    tasks = self._ready_batches.get(block=False)
  File "C:\Users\lakit\AppData\Local\Programs\Python\Python38\lib\queue.py", line 167, in get
    raise Empty
_queue.Empty

During handling of the above exception, another exception occurred:

Traceback (most recent call last):
  File "D:\Passion Projects\PavementResearch\venv\lib\site-packages\pycaret\internal\tabular.py", line 2183, in compare_models
    model, model_fit_time = create_model_supervised(
  File "D:\Passion Projects\PavementResearch\venv\lib\site-packages\pycaret\internal\tabular.py", line 3112, in create_model_supervised
    scores = cross_validate(
  File "D:\Passion Projects\PavementResearch\venv\lib\site-packages\sklearn\utils\validation.py", line 72, in inner_f
    return f(**kwargs)
  File "D:\Passion Projects\PavementResearch\venv\lib\site-packages\sklearn\model_selection\_validation.py", line 242, in cross_validate
    scores = parallel(
  File "D:\Passion Projects\PavementResearch\venv\lib\site-packages\joblib\parallel.py", line 1041, in __call__
    if self.dispatch_one_batch(iterator):
  File "D:\Passion Projects\PavementResearch\venv\lib\site-packages\joblib\parallel.py", line 831, in dispatch_one_batch
    islice = list(itertools.islice(iterator, big_batch_size))
  File "D:\Passion Projects\PavementResearch\venv\lib\site-packages\sklearn\model_selection\_validation.py", line 242, in <genexpr>
    scores = parallel(
  File "D:\Passion Projects\PavementResearch\venv\lib\site-packages\sklearn\model_selection\_split.py", line 331, in split
    raise ValueError(
ValueError: Cannot have number of splits n_splits=10 greater than the number of samples: n_samples=4.

2021-04-22 07:23:28,719:INFO:Initializing Lasso Least Angle Regression
2021-04-22 07:23:28,719:INFO:Total runtime is 0.0018832127253214518 minutes
2021-04-22 07:23:28,720:INFO:SubProcess create_model() called ==================================
2021-04-22 07:23:28,721:INFO:Initializing create_model()
2021-04-22 07:23:28,721:INFO:create_model(estimator=llar, fold=KFold(n_splits=10, random_state=None, shuffle=False), round=4, cross_validation=True, predict=True, fit_kwargs={}, groups=None, refit=False, verbose=False, system=False, metrics=None, display=<pycaret.internal.Display.Display object at 0x0000025CF9FD29A0>, kwargs={})
2021-04-22 07:23:28,721:INFO:Checking exceptions
2021-04-22 07:23:28,721:INFO:Importing libraries
2021-04-22 07:23:28,721:INFO:Copying training dataset
2021-04-22 07:23:28,721:INFO:Defining folds
2021-04-22 07:23:28,721:INFO:Declaring metric variables
2021-04-22 07:23:28,723:INFO:Importing untrained model
2021-04-22 07:23:28,724:INFO:Lasso Least Angle Regression Imported succesfully
2021-04-22 07:23:28,727:INFO:Starting cross validation
2021-04-22 07:23:28,728:INFO:Cross validating with KFold(n_splits=10, random_state=None, shuffle=False), n_jobs=-1
2021-04-22 07:23:28,728:WARNING:create_model() for llar raised an exception or returned all 0.0, trying without fit_kwargs:
2021-04-22 07:23:28,729:WARNING:Traceback (most recent call last):
  File "D:\Passion Projects\PavementResearch\venv\lib\site-packages\joblib\parallel.py", line 820, in dispatch_one_batch
    tasks = self._ready_batches.get(block=False)
  File "C:\Users\lakit\AppData\Local\Programs\Python\Python38\lib\queue.py", line 167, in get
    raise Empty
_queue.Empty

During handling of the above exception, another exception occurred:

Traceback (most recent call last):
  File "D:\Passion Projects\PavementResearch\venv\lib\site-packages\pycaret\internal\tabular.py", line 2163, in compare_models
    model, model_fit_time = create_model_supervised(
  File "D:\Passion Projects\PavementResearch\venv\lib\site-packages\pycaret\internal\tabular.py", line 3112, in create_model_supervised
    scores = cross_validate(
  File "D:\Passion Projects\PavementResearch\venv\lib\site-packages\sklearn\utils\validation.py", line 72, in inner_f
    return f(**kwargs)
  File "D:\Passion Projects\PavementResearch\venv\lib\site-packages\sklearn\model_selection\_validation.py", line 242, in cross_validate
    scores = parallel(
  File "D:\Passion Projects\PavementResearch\venv\lib\site-packages\joblib\parallel.py", line 1041, in __call__
    if self.dispatch_one_batch(iterator):
  File "D:\Passion Projects\PavementResearch\venv\lib\site-packages\joblib\parallel.py", line 831, in dispatch_one_batch
    islice = list(itertools.islice(iterator, big_batch_size))
  File "D:\Passion Projects\PavementResearch\venv\lib\site-packages\sklearn\model_selection\_validation.py", line 242, in <genexpr>
    scores = parallel(
  File "D:\Passion Projects\PavementResearch\venv\lib\site-packages\sklearn\model_selection\_split.py", line 331, in split
    raise ValueError(
ValueError: Cannot have number of splits n_splits=10 greater than the number of samples: n_samples=4.

2021-04-22 07:23:28,729:INFO:Initializing create_model()
2021-04-22 07:23:28,729:INFO:create_model(estimator=llar, fold=KFold(n_splits=10, random_state=None, shuffle=False), round=4, cross_validation=True, predict=True, fit_kwargs=None, groups=None, refit=False, verbose=False, system=False, metrics=None, display=<pycaret.internal.Display.Display object at 0x0000025CF9FD29A0>, kwargs={})
2021-04-22 07:23:28,729:INFO:Checking exceptions
2021-04-22 07:23:28,729:INFO:Importing libraries
2021-04-22 07:23:28,729:INFO:Copying training dataset
2021-04-22 07:23:28,729:INFO:Defining folds
2021-04-22 07:23:28,729:INFO:Declaring metric variables
2021-04-22 07:23:28,731:INFO:Importing untrained model
2021-04-22 07:23:28,733:INFO:Lasso Least Angle Regression Imported succesfully
2021-04-22 07:23:28,736:INFO:Starting cross validation
2021-04-22 07:23:28,736:INFO:Cross validating with KFold(n_splits=10, random_state=None, shuffle=False), n_jobs=-1
2021-04-22 07:23:28,737:ERROR:create_model() for llar raised an exception:
2021-04-22 07:23:28,737:ERROR:Traceback (most recent call last):
  File "D:\Passion Projects\PavementResearch\venv\lib\site-packages\joblib\parallel.py", line 820, in dispatch_one_batch
    tasks = self._ready_batches.get(block=False)
  File "C:\Users\lakit\AppData\Local\Programs\Python\Python38\lib\queue.py", line 167, in get
    raise Empty
_queue.Empty

During handling of the above exception, another exception occurred:

Traceback (most recent call last):
  File "D:\Passion Projects\PavementResearch\venv\lib\site-packages\pycaret\internal\tabular.py", line 2163, in compare_models
    model, model_fit_time = create_model_supervised(
  File "D:\Passion Projects\PavementResearch\venv\lib\site-packages\pycaret\internal\tabular.py", line 3112, in create_model_supervised
    scores = cross_validate(
  File "D:\Passion Projects\PavementResearch\venv\lib\site-packages\sklearn\utils\validation.py", line 72, in inner_f
    return f(**kwargs)
  File "D:\Passion Projects\PavementResearch\venv\lib\site-packages\sklearn\model_selection\_validation.py", line 242, in cross_validate
    scores = parallel(
  File "D:\Passion Projects\PavementResearch\venv\lib\site-packages\joblib\parallel.py", line 1041, in __call__
    if self.dispatch_one_batch(iterator):
  File "D:\Passion Projects\PavementResearch\venv\lib\site-packages\joblib\parallel.py", line 831, in dispatch_one_batch
    islice = list(itertools.islice(iterator, big_batch_size))
  File "D:\Passion Projects\PavementResearch\venv\lib\site-packages\sklearn\model_selection\_validation.py", line 242, in <genexpr>
    scores = parallel(
  File "D:\Passion Projects\PavementResearch\venv\lib\site-packages\sklearn\model_selection\_split.py", line 331, in split
    raise ValueError(
ValueError: Cannot have number of splits n_splits=10 greater than the number of samples: n_samples=4.

During handling of the above exception, another exception occurred:

Traceback (most recent call last):
  File "D:\Passion Projects\PavementResearch\venv\lib\site-packages\joblib\parallel.py", line 820, in dispatch_one_batch
    tasks = self._ready_batches.get(block=False)
  File "C:\Users\lakit\AppData\Local\Programs\Python\Python38\lib\queue.py", line 167, in get
    raise Empty
_queue.Empty

During handling of the above exception, another exception occurred:

Traceback (most recent call last):
  File "D:\Passion Projects\PavementResearch\venv\lib\site-packages\pycaret\internal\tabular.py", line 2183, in compare_models
    model, model_fit_time = create_model_supervised(
  File "D:\Passion Projects\PavementResearch\venv\lib\site-packages\pycaret\internal\tabular.py", line 3112, in create_model_supervised
    scores = cross_validate(
  File "D:\Passion Projects\PavementResearch\venv\lib\site-packages\sklearn\utils\validation.py", line 72, in inner_f
    return f(**kwargs)
  File "D:\Passion Projects\PavementResearch\venv\lib\site-packages\sklearn\model_selection\_validation.py", line 242, in cross_validate
    scores = parallel(
  File "D:\Passion Projects\PavementResearch\venv\lib\site-packages\joblib\parallel.py", line 1041, in __call__
    if self.dispatch_one_batch(iterator):
  File "D:\Passion Projects\PavementResearch\venv\lib\site-packages\joblib\parallel.py", line 831, in dispatch_one_batch
    islice = list(itertools.islice(iterator, big_batch_size))
  File "D:\Passion Projects\PavementResearch\venv\lib\site-packages\sklearn\model_selection\_validation.py", line 242, in <genexpr>
    scores = parallel(
  File "D:\Passion Projects\PavementResearch\venv\lib\site-packages\sklearn\model_selection\_split.py", line 331, in split
    raise ValueError(
ValueError: Cannot have number of splits n_splits=10 greater than the number of samples: n_samples=4.

2021-04-22 07:23:28,738:INFO:Initializing Orthogonal Matching Pursuit
2021-04-22 07:23:28,738:INFO:Total runtime is 0.002199427286783854 minutes
2021-04-22 07:23:28,739:INFO:SubProcess create_model() called ==================================
2021-04-22 07:23:28,739:INFO:Initializing create_model()
2021-04-22 07:23:28,740:INFO:create_model(estimator=omp, fold=KFold(n_splits=10, random_state=None, shuffle=False), round=4, cross_validation=True, predict=True, fit_kwargs={}, groups=None, refit=False, verbose=False, system=False, metrics=None, display=<pycaret.internal.Display.Display object at 0x0000025CF9FD29A0>, kwargs={})
2021-04-22 07:23:28,740:INFO:Checking exceptions
2021-04-22 07:23:28,740:INFO:Importing libraries
2021-04-22 07:23:28,740:INFO:Copying training dataset
2021-04-22 07:23:28,740:INFO:Defining folds
2021-04-22 07:23:28,740:INFO:Declaring metric variables
2021-04-22 07:23:28,741:INFO:Importing untrained model
2021-04-22 07:23:28,743:INFO:Orthogonal Matching Pursuit Imported succesfully
2021-04-22 07:23:28,746:INFO:Starting cross validation
2021-04-22 07:23:28,747:INFO:Cross validating with KFold(n_splits=10, random_state=None, shuffle=False), n_jobs=-1
2021-04-22 07:23:28,747:WARNING:create_model() for omp raised an exception or returned all 0.0, trying without fit_kwargs:
2021-04-22 07:23:28,748:WARNING:Traceback (most recent call last):
  File "D:\Passion Projects\PavementResearch\venv\lib\site-packages\joblib\parallel.py", line 820, in dispatch_one_batch
    tasks = self._ready_batches.get(block=False)
  File "C:\Users\lakit\AppData\Local\Programs\Python\Python38\lib\queue.py", line 167, in get
    raise Empty
_queue.Empty

During handling of the above exception, another exception occurred:

Traceback (most recent call last):
  File "D:\Passion Projects\PavementResearch\venv\lib\site-packages\pycaret\internal\tabular.py", line 2163, in compare_models
    model, model_fit_time = create_model_supervised(
  File "D:\Passion Projects\PavementResearch\venv\lib\site-packages\pycaret\internal\tabular.py", line 3112, in create_model_supervised
    scores = cross_validate(
  File "D:\Passion Projects\PavementResearch\venv\lib\site-packages\sklearn\utils\validation.py", line 72, in inner_f
    return f(**kwargs)
  File "D:\Passion Projects\PavementResearch\venv\lib\site-packages\sklearn\model_selection\_validation.py", line 242, in cross_validate
    scores = parallel(
  File "D:\Passion Projects\PavementResearch\venv\lib\site-packages\joblib\parallel.py", line 1041, in __call__
    if self.dispatch_one_batch(iterator):
  File "D:\Passion Projects\PavementResearch\venv\lib\site-packages\joblib\parallel.py", line 831, in dispatch_one_batch
    islice = list(itertools.islice(iterator, big_batch_size))
  File "D:\Passion Projects\PavementResearch\venv\lib\site-packages\sklearn\model_selection\_validation.py", line 242, in <genexpr>
    scores = parallel(
  File "D:\Passion Projects\PavementResearch\venv\lib\site-packages\sklearn\model_selection\_split.py", line 331, in split
    raise ValueError(
ValueError: Cannot have number of splits n_splits=10 greater than the number of samples: n_samples=4.

2021-04-22 07:23:28,748:INFO:Initializing create_model()
2021-04-22 07:23:28,748:INFO:create_model(estimator=omp, fold=KFold(n_splits=10, random_state=None, shuffle=False), round=4, cross_validation=True, predict=True, fit_kwargs=None, groups=None, refit=False, verbose=False, system=False, metrics=None, display=<pycaret.internal.Display.Display object at 0x0000025CF9FD29A0>, kwargs={})
2021-04-22 07:23:28,748:INFO:Checking exceptions
2021-04-22 07:23:28,748:INFO:Importing libraries
2021-04-22 07:23:28,748:INFO:Copying training dataset
2021-04-22 07:23:28,748:INFO:Defining folds
2021-04-22 07:23:28,748:INFO:Declaring metric variables
2021-04-22 07:23:28,750:INFO:Importing untrained model
2021-04-22 07:23:28,752:INFO:Orthogonal Matching Pursuit Imported succesfully
2021-04-22 07:23:28,755:INFO:Starting cross validation
2021-04-22 07:23:28,755:INFO:Cross validating with KFold(n_splits=10, random_state=None, shuffle=False), n_jobs=-1
2021-04-22 07:23:28,884:ERROR:create_model() for omp raised an exception:
2021-04-22 07:23:28,884:ERROR:Traceback (most recent call last):
  File "D:\Passion Projects\PavementResearch\venv\lib\site-packages\joblib\parallel.py", line 820, in dispatch_one_batch
    tasks = self._ready_batches.get(block=False)
  File "C:\Users\lakit\AppData\Local\Programs\Python\Python38\lib\queue.py", line 167, in get
    raise Empty
_queue.Empty

During handling of the above exception, another exception occurred:

Traceback (most recent call last):
  File "D:\Passion Projects\PavementResearch\venv\lib\site-packages\pycaret\internal\tabular.py", line 2163, in compare_models
    model, model_fit_time = create_model_supervised(
  File "D:\Passion Projects\PavementResearch\venv\lib\site-packages\pycaret\internal\tabular.py", line 3112, in create_model_supervised
    scores = cross_validate(
  File "D:\Passion Projects\PavementResearch\venv\lib\site-packages\sklearn\utils\validation.py", line 72, in inner_f
    return f(**kwargs)
  File "D:\Passion Projects\PavementResearch\venv\lib\site-packages\sklearn\model_selection\_validation.py", line 242, in cross_validate
    scores = parallel(
  File "D:\Passion Projects\PavementResearch\venv\lib\site-packages\joblib\parallel.py", line 1041, in __call__
    if self.dispatch_one_batch(iterator):
  File "D:\Passion Projects\PavementResearch\venv\lib\site-packages\joblib\parallel.py", line 831, in dispatch_one_batch
    islice = list(itertools.islice(iterator, big_batch_size))
  File "D:\Passion Projects\PavementResearch\venv\lib\site-packages\sklearn\model_selection\_validation.py", line 242, in <genexpr>
    scores = parallel(
  File "D:\Passion Projects\PavementResearch\venv\lib\site-packages\sklearn\model_selection\_split.py", line 331, in split
    raise ValueError(
ValueError: Cannot have number of splits n_splits=10 greater than the number of samples: n_samples=4.

During handling of the above exception, another exception occurred:

Traceback (most recent call last):
  File "D:\Passion Projects\PavementResearch\venv\lib\site-packages\joblib\parallel.py", line 820, in dispatch_one_batch
    tasks = self._ready_batches.get(block=False)
  File "C:\Users\lakit\AppData\Local\Programs\Python\Python38\lib\queue.py", line 167, in get
    raise Empty
_queue.Empty

During handling of the above exception, another exception occurred:

Traceback (most recent call last):
  File "D:\Passion Projects\PavementResearch\venv\lib\site-packages\pycaret\internal\tabular.py", line 2183, in compare_models
    model, model_fit_time = create_model_supervised(
  File "D:\Passion Projects\PavementResearch\venv\lib\site-packages\pycaret\internal\tabular.py", line 3112, in create_model_supervised
    scores = cross_validate(
  File "D:\Passion Projects\PavementResearch\venv\lib\site-packages\sklearn\utils\validation.py", line 72, in inner_f
    return f(**kwargs)
  File "D:\Passion Projects\PavementResearch\venv\lib\site-packages\sklearn\model_selection\_validation.py", line 242, in cross_validate
    scores = parallel(
  File "D:\Passion Projects\PavementResearch\venv\lib\site-packages\joblib\parallel.py", line 1041, in __call__
    if self.dispatch_one_batch(iterator):
  File "D:\Passion Projects\PavementResearch\venv\lib\site-packages\joblib\parallel.py", line 831, in dispatch_one_batch
    islice = list(itertools.islice(iterator, big_batch_size))
  File "D:\Passion Projects\PavementResearch\venv\lib\site-packages\sklearn\model_selection\_validation.py", line 242, in <genexpr>
    scores = parallel(
  File "D:\Passion Projects\PavementResearch\venv\lib\site-packages\sklearn\model_selection\_split.py", line 331, in split
    raise ValueError(
ValueError: Cannot have number of splits n_splits=10 greater than the number of samples: n_samples=4.

2021-04-22 07:23:28,884:INFO:Initializing Bayesian Ridge
2021-04-22 07:23:28,884:INFO:Total runtime is 0.004632763067881266 minutes
2021-04-22 07:23:28,886:INFO:SubProcess create_model() called ==================================
2021-04-22 07:23:28,886:INFO:Initializing create_model()
2021-04-22 07:23:28,887:INFO:create_model(estimator=br, fold=KFold(n_splits=10, random_state=None, shuffle=False), round=4, cross_validation=True, predict=True, fit_kwargs={}, groups=None, refit=False, verbose=False, system=False, metrics=None, display=<pycaret.internal.Display.Display object at 0x0000025CF9FD29A0>, kwargs={})
2021-04-22 07:23:28,887:INFO:Checking exceptions
2021-04-22 07:23:28,887:INFO:Importing libraries
2021-04-22 07:23:28,887:INFO:Copying training dataset
2021-04-22 07:23:28,887:INFO:Defining folds
2021-04-22 07:23:28,887:INFO:Declaring metric variables
2021-04-22 07:23:28,889:INFO:Importing untrained model
2021-04-22 07:23:28,890:INFO:Bayesian Ridge Imported succesfully
2021-04-22 07:23:28,894:INFO:Starting cross validation
2021-04-22 07:23:28,894:INFO:Cross validating with KFold(n_splits=10, random_state=None, shuffle=False), n_jobs=-1
2021-04-22 07:23:28,894:WARNING:create_model() for br raised an exception or returned all 0.0, trying without fit_kwargs:
2021-04-22 07:23:28,895:WARNING:Traceback (most recent call last):
  File "D:\Passion Projects\PavementResearch\venv\lib\site-packages\joblib\parallel.py", line 820, in dispatch_one_batch
    tasks = self._ready_batches.get(block=False)
  File "C:\Users\lakit\AppData\Local\Programs\Python\Python38\lib\queue.py", line 167, in get
    raise Empty
_queue.Empty

During handling of the above exception, another exception occurred:

Traceback (most recent call last):
  File "D:\Passion Projects\PavementResearch\venv\lib\site-packages\pycaret\internal\tabular.py", line 2163, in compare_models
    model, model_fit_time = create_model_supervised(
  File "D:\Passion Projects\PavementResearch\venv\lib\site-packages\pycaret\internal\tabular.py", line 3112, in create_model_supervised
    scores = cross_validate(
  File "D:\Passion Projects\PavementResearch\venv\lib\site-packages\sklearn\utils\validation.py", line 72, in inner_f
    return f(**kwargs)
  File "D:\Passion Projects\PavementResearch\venv\lib\site-packages\sklearn\model_selection\_validation.py", line 242, in cross_validate
    scores = parallel(
  File "D:\Passion Projects\PavementResearch\venv\lib\site-packages\joblib\parallel.py", line 1041, in __call__
    if self.dispatch_one_batch(iterator):
  File "D:\Passion Projects\PavementResearch\venv\lib\site-packages\joblib\parallel.py", line 831, in dispatch_one_batch
    islice = list(itertools.islice(iterator, big_batch_size))
  File "D:\Passion Projects\PavementResearch\venv\lib\site-packages\sklearn\model_selection\_validation.py", line 242, in <genexpr>
    scores = parallel(
  File "D:\Passion Projects\PavementResearch\venv\lib\site-packages\sklearn\model_selection\_split.py", line 331, in split
    raise ValueError(
ValueError: Cannot have number of splits n_splits=10 greater than the number of samples: n_samples=4.

2021-04-22 07:23:28,895:INFO:Initializing create_model()
2021-04-22 07:23:28,895:INFO:create_model(estimator=br, fold=KFold(n_splits=10, random_state=None, shuffle=False), round=4, cross_validation=True, predict=True, fit_kwargs=None, groups=None, refit=False, verbose=False, system=False, metrics=None, display=<pycaret.internal.Display.Display object at 0x0000025CF9FD29A0>, kwargs={})
2021-04-22 07:23:28,895:INFO:Checking exceptions
2021-04-22 07:23:28,895:INFO:Importing libraries
2021-04-22 07:23:28,895:INFO:Copying training dataset
2021-04-22 07:23:28,895:INFO:Defining folds
2021-04-22 07:23:28,895:INFO:Declaring metric variables
2021-04-22 07:23:28,897:INFO:Importing untrained model
2021-04-22 07:23:28,899:INFO:Bayesian Ridge Imported succesfully
2021-04-22 07:23:28,902:INFO:Starting cross validation
2021-04-22 07:23:28,902:INFO:Cross validating with KFold(n_splits=10, random_state=None, shuffle=False), n_jobs=-1
2021-04-22 07:23:28,903:ERROR:create_model() for br raised an exception:
2021-04-22 07:23:28,903:ERROR:Traceback (most recent call last):
  File "D:\Passion Projects\PavementResearch\venv\lib\site-packages\joblib\parallel.py", line 820, in dispatch_one_batch
    tasks = self._ready_batches.get(block=False)
  File "C:\Users\lakit\AppData\Local\Programs\Python\Python38\lib\queue.py", line 167, in get
    raise Empty
_queue.Empty

During handling of the above exception, another exception occurred:

Traceback (most recent call last):
  File "D:\Passion Projects\PavementResearch\venv\lib\site-packages\pycaret\internal\tabular.py", line 2163, in compare_models
    model, model_fit_time = create_model_supervised(
  File "D:\Passion Projects\PavementResearch\venv\lib\site-packages\pycaret\internal\tabular.py", line 3112, in create_model_supervised
    scores = cross_validate(
  File "D:\Passion Projects\PavementResearch\venv\lib\site-packages\sklearn\utils\validation.py", line 72, in inner_f
    return f(**kwargs)
  File "D:\Passion Projects\PavementResearch\venv\lib\site-packages\sklearn\model_selection\_validation.py", line 242, in cross_validate
    scores = parallel(
  File "D:\Passion Projects\PavementResearch\venv\lib\site-packages\joblib\parallel.py", line 1041, in __call__
    if self.dispatch_one_batch(iterator):
  File "D:\Passion Projects\PavementResearch\venv\lib\site-packages\joblib\parallel.py", line 831, in dispatch_one_batch
    islice = list(itertools.islice(iterator, big_batch_size))
  File "D:\Passion Projects\PavementResearch\venv\lib\site-packages\sklearn\model_selection\_validation.py", line 242, in <genexpr>
    scores = parallel(
  File "D:\Passion Projects\PavementResearch\venv\lib\site-packages\sklearn\model_selection\_split.py", line 331, in split
    raise ValueError(
ValueError: Cannot have number of splits n_splits=10 greater than the number of samples: n_samples=4.

During handling of the above exception, another exception occurred:

Traceback (most recent call last):
  File "D:\Passion Projects\PavementResearch\venv\lib\site-packages\joblib\parallel.py", line 820, in dispatch_one_batch
    tasks = self._ready_batches.get(block=False)
  File "C:\Users\lakit\AppData\Local\Programs\Python\Python38\lib\queue.py", line 167, in get
    raise Empty
_queue.Empty

During handling of the above exception, another exception occurred:

Traceback (most recent call last):
  File "D:\Passion Projects\PavementResearch\venv\lib\site-packages\pycaret\internal\tabular.py", line 2183, in compare_models
    model, model_fit_time = create_model_supervised(
  File "D:\Passion Projects\PavementResearch\venv\lib\site-packages\pycaret\internal\tabular.py", line 3112, in create_model_supervised
    scores = cross_validate(
  File "D:\Passion Projects\PavementResearch\venv\lib\site-packages\sklearn\utils\validation.py", line 72, in inner_f
    return f(**kwargs)
  File "D:\Passion Projects\PavementResearch\venv\lib\site-packages\sklearn\model_selection\_validation.py", line 242, in cross_validate
    scores = parallel(
  File "D:\Passion Projects\PavementResearch\venv\lib\site-packages\joblib\parallel.py", line 1041, in __call__
    if self.dispatch_one_batch(iterator):
  File "D:\Passion Projects\PavementResearch\venv\lib\site-packages\joblib\parallel.py", line 831, in dispatch_one_batch
    islice = list(itertools.islice(iterator, big_batch_size))
  File "D:\Passion Projects\PavementResearch\venv\lib\site-packages\sklearn\model_selection\_validation.py", line 242, in <genexpr>
    scores = parallel(
  File "D:\Passion Projects\PavementResearch\venv\lib\site-packages\sklearn\model_selection\_split.py", line 331, in split
    raise ValueError(
ValueError: Cannot have number of splits n_splits=10 greater than the number of samples: n_samples=4.

2021-04-22 07:23:28,904:INFO:Initializing Passive Aggressive Regressor
2021-04-22 07:23:28,904:INFO:Total runtime is 0.004966096083323161 minutes
2021-04-22 07:23:28,905:INFO:SubProcess create_model() called ==================================
2021-04-22 07:23:28,905:INFO:Initializing create_model()
2021-04-22 07:23:28,905:INFO:create_model(estimator=par, fold=KFold(n_splits=10, random_state=None, shuffle=False), round=4, cross_validation=True, predict=True, fit_kwargs={}, groups=None, refit=False, verbose=False, system=False, metrics=None, display=<pycaret.internal.Display.Display object at 0x0000025CF9FD29A0>, kwargs={})
2021-04-22 07:23:28,906:INFO:Checking exceptions
2021-04-22 07:23:28,906:INFO:Importing libraries
2021-04-22 07:23:28,906:INFO:Copying training dataset
2021-04-22 07:23:28,906:INFO:Defining folds
2021-04-22 07:23:28,906:INFO:Declaring metric variables
2021-04-22 07:23:28,907:INFO:Importing untrained model
2021-04-22 07:23:28,909:INFO:Passive Aggressive Regressor Imported succesfully
2021-04-22 07:23:28,912:INFO:Starting cross validation
2021-04-22 07:23:28,913:INFO:Cross validating with KFold(n_splits=10, random_state=None, shuffle=False), n_jobs=-1
2021-04-22 07:23:28,913:WARNING:create_model() for par raised an exception or returned all 0.0, trying without fit_kwargs:
2021-04-22 07:23:28,914:WARNING:Traceback (most recent call last):
  File "D:\Passion Projects\PavementResearch\venv\lib\site-packages\joblib\parallel.py", line 820, in dispatch_one_batch
    tasks = self._ready_batches.get(block=False)
  File "C:\Users\lakit\AppData\Local\Programs\Python\Python38\lib\queue.py", line 167, in get
    raise Empty
_queue.Empty

During handling of the above exception, another exception occurred:

Traceback (most recent call last):
  File "D:\Passion Projects\PavementResearch\venv\lib\site-packages\pycaret\internal\tabular.py", line 2163, in compare_models
    model, model_fit_time = create_model_supervised(
  File "D:\Passion Projects\PavementResearch\venv\lib\site-packages\pycaret\internal\tabular.py", line 3112, in create_model_supervised
    scores = cross_validate(
  File "D:\Passion Projects\PavementResearch\venv\lib\site-packages\sklearn\utils\validation.py", line 72, in inner_f
    return f(**kwargs)
  File "D:\Passion Projects\PavementResearch\venv\lib\site-packages\sklearn\model_selection\_validation.py", line 242, in cross_validate
    scores = parallel(
  File "D:\Passion Projects\PavementResearch\venv\lib\site-packages\joblib\parallel.py", line 1041, in __call__
    if self.dispatch_one_batch(iterator):
  File "D:\Passion Projects\PavementResearch\venv\lib\site-packages\joblib\parallel.py", line 831, in dispatch_one_batch
    islice = list(itertools.islice(iterator, big_batch_size))
  File "D:\Passion Projects\PavementResearch\venv\lib\site-packages\sklearn\model_selection\_validation.py", line 242, in <genexpr>
    scores = parallel(
  File "D:\Passion Projects\PavementResearch\venv\lib\site-packages\sklearn\model_selection\_split.py", line 331, in split
    raise ValueError(
ValueError: Cannot have number of splits n_splits=10 greater than the number of samples: n_samples=4.

2021-04-22 07:23:28,914:INFO:Initializing create_model()
2021-04-22 07:23:28,914:INFO:create_model(estimator=par, fold=KFold(n_splits=10, random_state=None, shuffle=False), round=4, cross_validation=True, predict=True, fit_kwargs=None, groups=None, refit=False, verbose=False, system=False, metrics=None, display=<pycaret.internal.Display.Display object at 0x0000025CF9FD29A0>, kwargs={})
2021-04-22 07:23:28,914:INFO:Checking exceptions
2021-04-22 07:23:28,914:INFO:Importing libraries
2021-04-22 07:23:28,914:INFO:Copying training dataset
2021-04-22 07:23:28,914:INFO:Defining folds
2021-04-22 07:23:28,914:INFO:Declaring metric variables
2021-04-22 07:23:28,916:INFO:Importing untrained model
2021-04-22 07:23:28,918:INFO:Passive Aggressive Regressor Imported succesfully
2021-04-22 07:23:28,921:INFO:Starting cross validation
2021-04-22 07:23:28,921:INFO:Cross validating with KFold(n_splits=10, random_state=None, shuffle=False), n_jobs=-1
2021-04-22 07:23:28,922:ERROR:create_model() for par raised an exception:
2021-04-22 07:23:28,922:ERROR:Traceback (most recent call last):
  File "D:\Passion Projects\PavementResearch\venv\lib\site-packages\joblib\parallel.py", line 820, in dispatch_one_batch
    tasks = self._ready_batches.get(block=False)
  File "C:\Users\lakit\AppData\Local\Programs\Python\Python38\lib\queue.py", line 167, in get
    raise Empty
_queue.Empty

During handling of the above exception, another exception occurred:

Traceback (most recent call last):
  File "D:\Passion Projects\PavementResearch\venv\lib\site-packages\pycaret\internal\tabular.py", line 2163, in compare_models
    model, model_fit_time = create_model_supervised(
  File "D:\Passion Projects\PavementResearch\venv\lib\site-packages\pycaret\internal\tabular.py", line 3112, in create_model_supervised
    scores = cross_validate(
  File "D:\Passion Projects\PavementResearch\venv\lib\site-packages\sklearn\utils\validation.py", line 72, in inner_f
    return f(**kwargs)
  File "D:\Passion Projects\PavementResearch\venv\lib\site-packages\sklearn\model_selection\_validation.py", line 242, in cross_validate
    scores = parallel(
  File "D:\Passion Projects\PavementResearch\venv\lib\site-packages\joblib\parallel.py", line 1041, in __call__
    if self.dispatch_one_batch(iterator):
  File "D:\Passion Projects\PavementResearch\venv\lib\site-packages\joblib\parallel.py", line 831, in dispatch_one_batch
    islice = list(itertools.islice(iterator, big_batch_size))
  File "D:\Passion Projects\PavementResearch\venv\lib\site-packages\sklearn\model_selection\_validation.py", line 242, in <genexpr>
    scores = parallel(
  File "D:\Passion Projects\PavementResearch\venv\lib\site-packages\sklearn\model_selection\_split.py", line 331, in split
    raise ValueError(
ValueError: Cannot have number of splits n_splits=10 greater than the number of samples: n_samples=4.

During handling of the above exception, another exception occurred:

Traceback (most recent call last):
  File "D:\Passion Projects\PavementResearch\venv\lib\site-packages\joblib\parallel.py", line 820, in dispatch_one_batch
    tasks = self._ready_batches.get(block=False)
  File "C:\Users\lakit\AppData\Local\Programs\Python\Python38\lib\queue.py", line 167, in get
    raise Empty
_queue.Empty

During handling of the above exception, another exception occurred:

Traceback (most recent call last):
  File "D:\Passion Projects\PavementResearch\venv\lib\site-packages\pycaret\internal\tabular.py", line 2183, in compare_models
    model, model_fit_time = create_model_supervised(
  File "D:\Passion Projects\PavementResearch\venv\lib\site-packages\pycaret\internal\tabular.py", line 3112, in create_model_supervised
    scores = cross_validate(
  File "D:\Passion Projects\PavementResearch\venv\lib\site-packages\sklearn\utils\validation.py", line 72, in inner_f
    return f(**kwargs)
  File "D:\Passion Projects\PavementResearch\venv\lib\site-packages\sklearn\model_selection\_validation.py", line 242, in cross_validate
    scores = parallel(
  File "D:\Passion Projects\PavementResearch\venv\lib\site-packages\joblib\parallel.py", line 1041, in __call__
    if self.dispatch_one_batch(iterator):
  File "D:\Passion Projects\PavementResearch\venv\lib\site-packages\joblib\parallel.py", line 831, in dispatch_one_batch
    islice = list(itertools.islice(iterator, big_batch_size))
  File "D:\Passion Projects\PavementResearch\venv\lib\site-packages\sklearn\model_selection\_validation.py", line 242, in <genexpr>
    scores = parallel(
  File "D:\Passion Projects\PavementResearch\venv\lib\site-packages\sklearn\model_selection\_split.py", line 331, in split
    raise ValueError(
ValueError: Cannot have number of splits n_splits=10 greater than the number of samples: n_samples=4.

2021-04-22 07:23:28,923:INFO:Initializing Huber Regressor
2021-04-22 07:23:28,923:INFO:Total runtime is 0.005282763640085856 minutes
2021-04-22 07:23:28,924:INFO:SubProcess create_model() called ==================================
2021-04-22 07:23:28,924:INFO:Initializing create_model()
2021-04-22 07:23:28,924:INFO:create_model(estimator=huber, fold=KFold(n_splits=10, random_state=None, shuffle=False), round=4, cross_validation=True, predict=True, fit_kwargs={}, groups=None, refit=False, verbose=False, system=False, metrics=None, display=<pycaret.internal.Display.Display object at 0x0000025CF9FD29A0>, kwargs={})
2021-04-22 07:23:28,924:INFO:Checking exceptions
2021-04-22 07:23:28,924:INFO:Importing libraries
2021-04-22 07:23:28,925:INFO:Copying training dataset
2021-04-22 07:23:28,925:INFO:Defining folds
2021-04-22 07:23:28,925:INFO:Declaring metric variables
2021-04-22 07:23:28,926:INFO:Importing untrained model
2021-04-22 07:23:28,928:INFO:Huber Regressor Imported succesfully
2021-04-22 07:23:28,931:INFO:Starting cross validation
2021-04-22 07:23:28,931:INFO:Cross validating with KFold(n_splits=10, random_state=None, shuffle=False), n_jobs=-1
2021-04-22 07:23:28,932:WARNING:create_model() for huber raised an exception or returned all 0.0, trying without fit_kwargs:
2021-04-22 07:23:28,932:WARNING:Traceback (most recent call last):
  File "D:\Passion Projects\PavementResearch\venv\lib\site-packages\joblib\parallel.py", line 820, in dispatch_one_batch
    tasks = self._ready_batches.get(block=False)
  File "C:\Users\lakit\AppData\Local\Programs\Python\Python38\lib\queue.py", line 167, in get
    raise Empty
_queue.Empty

During handling of the above exception, another exception occurred:

Traceback (most recent call last):
  File "D:\Passion Projects\PavementResearch\venv\lib\site-packages\pycaret\internal\tabular.py", line 2163, in compare_models
    model, model_fit_time = create_model_supervised(
  File "D:\Passion Projects\PavementResearch\venv\lib\site-packages\pycaret\internal\tabular.py", line 3112, in create_model_supervised
    scores = cross_validate(
  File "D:\Passion Projects\PavementResearch\venv\lib\site-packages\sklearn\utils\validation.py", line 72, in inner_f
    return f(**kwargs)
  File "D:\Passion Projects\PavementResearch\venv\lib\site-packages\sklearn\model_selection\_validation.py", line 242, in cross_validate
    scores = parallel(
  File "D:\Passion Projects\PavementResearch\venv\lib\site-packages\joblib\parallel.py", line 1041, in __call__
    if self.dispatch_one_batch(iterator):
  File "D:\Passion Projects\PavementResearch\venv\lib\site-packages\joblib\parallel.py", line 831, in dispatch_one_batch
    islice = list(itertools.islice(iterator, big_batch_size))
  File "D:\Passion Projects\PavementResearch\venv\lib\site-packages\sklearn\model_selection\_validation.py", line 242, in <genexpr>
    scores = parallel(
  File "D:\Passion Projects\PavementResearch\venv\lib\site-packages\sklearn\model_selection\_split.py", line 331, in split
    raise ValueError(
ValueError: Cannot have number of splits n_splits=10 greater than the number of samples: n_samples=4.

2021-04-22 07:23:28,933:INFO:Initializing create_model()
2021-04-22 07:23:28,933:INFO:create_model(estimator=huber, fold=KFold(n_splits=10, random_state=None, shuffle=False), round=4, cross_validation=True, predict=True, fit_kwargs=None, groups=None, refit=False, verbose=False, system=False, metrics=None, display=<pycaret.internal.Display.Display object at 0x0000025CF9FD29A0>, kwargs={})
2021-04-22 07:23:28,933:INFO:Checking exceptions
2021-04-22 07:23:28,933:INFO:Importing libraries
2021-04-22 07:23:28,933:INFO:Copying training dataset
2021-04-22 07:23:28,933:INFO:Defining folds
2021-04-22 07:23:28,933:INFO:Declaring metric variables
2021-04-22 07:23:28,935:INFO:Importing untrained model
2021-04-22 07:23:28,936:INFO:Huber Regressor Imported succesfully
2021-04-22 07:23:28,940:INFO:Starting cross validation
2021-04-22 07:23:28,940:INFO:Cross validating with KFold(n_splits=10, random_state=None, shuffle=False), n_jobs=-1
2021-04-22 07:23:28,940:ERROR:create_model() for huber raised an exception:
2021-04-22 07:23:28,941:ERROR:Traceback (most recent call last):
  File "D:\Passion Projects\PavementResearch\venv\lib\site-packages\joblib\parallel.py", line 820, in dispatch_one_batch
    tasks = self._ready_batches.get(block=False)
  File "C:\Users\lakit\AppData\Local\Programs\Python\Python38\lib\queue.py", line 167, in get
    raise Empty
_queue.Empty

During handling of the above exception, another exception occurred:

Traceback (most recent call last):
  File "D:\Passion Projects\PavementResearch\venv\lib\site-packages\pycaret\internal\tabular.py", line 2163, in compare_models
    model, model_fit_time = create_model_supervised(
  File "D:\Passion Projects\PavementResearch\venv\lib\site-packages\pycaret\internal\tabular.py", line 3112, in create_model_supervised
    scores = cross_validate(
  File "D:\Passion Projects\PavementResearch\venv\lib\site-packages\sklearn\utils\validation.py", line 72, in inner_f
    return f(**kwargs)
  File "D:\Passion Projects\PavementResearch\venv\lib\site-packages\sklearn\model_selection\_validation.py", line 242, in cross_validate
    scores = parallel(
  File "D:\Passion Projects\PavementResearch\venv\lib\site-packages\joblib\parallel.py", line 1041, in __call__
    if self.dispatch_one_batch(iterator):
  File "D:\Passion Projects\PavementResearch\venv\lib\site-packages\joblib\parallel.py", line 831, in dispatch_one_batch
    islice = list(itertools.islice(iterator, big_batch_size))
  File "D:\Passion Projects\PavementResearch\venv\lib\site-packages\sklearn\model_selection\_validation.py", line 242, in <genexpr>
    scores = parallel(
  File "D:\Passion Projects\PavementResearch\venv\lib\site-packages\sklearn\model_selection\_split.py", line 331, in split
    raise ValueError(
ValueError: Cannot have number of splits n_splits=10 greater than the number of samples: n_samples=4.

During handling of the above exception, another exception occurred:

Traceback (most recent call last):
  File "D:\Passion Projects\PavementResearch\venv\lib\site-packages\joblib\parallel.py", line 820, in dispatch_one_batch
    tasks = self._ready_batches.get(block=False)
  File "C:\Users\lakit\AppData\Local\Programs\Python\Python38\lib\queue.py", line 167, in get
    raise Empty
_queue.Empty

During handling of the above exception, another exception occurred:

Traceback (most recent call last):
  File "D:\Passion Projects\PavementResearch\venv\lib\site-packages\pycaret\internal\tabular.py", line 2183, in compare_models
    model, model_fit_time = create_model_supervised(
  File "D:\Passion Projects\PavementResearch\venv\lib\site-packages\pycaret\internal\tabular.py", line 3112, in create_model_supervised
    scores = cross_validate(
  File "D:\Passion Projects\PavementResearch\venv\lib\site-packages\sklearn\utils\validation.py", line 72, in inner_f
    return f(**kwargs)
  File "D:\Passion Projects\PavementResearch\venv\lib\site-packages\sklearn\model_selection\_validation.py", line 242, in cross_validate
    scores = parallel(
  File "D:\Passion Projects\PavementResearch\venv\lib\site-packages\joblib\parallel.py", line 1041, in __call__
    if self.dispatch_one_batch(iterator):
  File "D:\Passion Projects\PavementResearch\venv\lib\site-packages\joblib\parallel.py", line 831, in dispatch_one_batch
    islice = list(itertools.islice(iterator, big_batch_size))
  File "D:\Passion Projects\PavementResearch\venv\lib\site-packages\sklearn\model_selection\_validation.py", line 242, in <genexpr>
    scores = parallel(
  File "D:\Passion Projects\PavementResearch\venv\lib\site-packages\sklearn\model_selection\_split.py", line 331, in split
    raise ValueError(
ValueError: Cannot have number of splits n_splits=10 greater than the number of samples: n_samples=4.

2021-04-22 07:23:28,941:INFO:Initializing K Neighbors Regressor
2021-04-22 07:23:28,941:INFO:Total runtime is 0.005582761764526367 minutes
2021-04-22 07:23:28,943:INFO:SubProcess create_model() called ==================================
2021-04-22 07:23:28,943:INFO:Initializing create_model()
2021-04-22 07:23:28,943:INFO:create_model(estimator=knn, fold=KFold(n_splits=10, random_state=None, shuffle=False), round=4, cross_validation=True, predict=True, fit_kwargs={}, groups=None, refit=False, verbose=False, system=False, metrics=None, display=<pycaret.internal.Display.Display object at 0x0000025CF9FD29A0>, kwargs={})
2021-04-22 07:23:28,943:INFO:Checking exceptions
2021-04-22 07:23:28,943:INFO:Importing libraries
2021-04-22 07:23:28,943:INFO:Copying training dataset
2021-04-22 07:23:28,943:INFO:Defining folds
2021-04-22 07:23:28,943:INFO:Declaring metric variables
2021-04-22 07:23:28,945:INFO:Importing untrained model
2021-04-22 07:23:28,947:INFO:K Neighbors Regressor Imported succesfully
2021-04-22 07:23:28,951:INFO:Starting cross validation
2021-04-22 07:23:28,951:INFO:Cross validating with KFold(n_splits=10, random_state=None, shuffle=False), n_jobs=-1
2021-04-22 07:23:28,952:WARNING:create_model() for knn raised an exception or returned all 0.0, trying without fit_kwargs:
2021-04-22 07:23:28,952:WARNING:Traceback (most recent call last):
  File "D:\Passion Projects\PavementResearch\venv\lib\site-packages\joblib\parallel.py", line 820, in dispatch_one_batch
    tasks = self._ready_batches.get(block=False)
  File "C:\Users\lakit\AppData\Local\Programs\Python\Python38\lib\queue.py", line 167, in get
    raise Empty
_queue.Empty

During handling of the above exception, another exception occurred:

Traceback (most recent call last):
  File "D:\Passion Projects\PavementResearch\venv\lib\site-packages\pycaret\internal\tabular.py", line 2163, in compare_models
    model, model_fit_time = create_model_supervised(
  File "D:\Passion Projects\PavementResearch\venv\lib\site-packages\pycaret\internal\tabular.py", line 3112, in create_model_supervised
    scores = cross_validate(
  File "D:\Passion Projects\PavementResearch\venv\lib\site-packages\sklearn\utils\validation.py", line 72, in inner_f
    return f(**kwargs)
  File "D:\Passion Projects\PavementResearch\venv\lib\site-packages\sklearn\model_selection\_validation.py", line 242, in cross_validate
    scores = parallel(
  File "D:\Passion Projects\PavementResearch\venv\lib\site-packages\joblib\parallel.py", line 1041, in __call__
    if self.dispatch_one_batch(iterator):
  File "D:\Passion Projects\PavementResearch\venv\lib\site-packages\joblib\parallel.py", line 831, in dispatch_one_batch
    islice = list(itertools.islice(iterator, big_batch_size))
  File "D:\Passion Projects\PavementResearch\venv\lib\site-packages\sklearn\model_selection\_validation.py", line 242, in <genexpr>
    scores = parallel(
  File "D:\Passion Projects\PavementResearch\venv\lib\site-packages\sklearn\model_selection\_split.py", line 331, in split
    raise ValueError(
ValueError: Cannot have number of splits n_splits=10 greater than the number of samples: n_samples=4.

2021-04-22 07:23:28,952:INFO:Initializing create_model()
2021-04-22 07:23:28,952:INFO:create_model(estimator=knn, fold=KFold(n_splits=10, random_state=None, shuffle=False), round=4, cross_validation=True, predict=True, fit_kwargs=None, groups=None, refit=False, verbose=False, system=False, metrics=None, display=<pycaret.internal.Display.Display object at 0x0000025CF9FD29A0>, kwargs={})
2021-04-22 07:23:28,952:INFO:Checking exceptions
2021-04-22 07:23:28,952:INFO:Importing libraries
2021-04-22 07:23:28,952:INFO:Copying training dataset
2021-04-22 07:23:28,952:INFO:Defining folds
2021-04-22 07:23:28,952:INFO:Declaring metric variables
2021-04-22 07:23:28,953:INFO:Importing untrained model
2021-04-22 07:23:28,955:INFO:K Neighbors Regressor Imported succesfully
2021-04-22 07:23:28,959:INFO:Starting cross validation
2021-04-22 07:23:28,959:INFO:Cross validating with KFold(n_splits=10, random_state=None, shuffle=False), n_jobs=-1
2021-04-22 07:23:28,959:ERROR:create_model() for knn raised an exception:
2021-04-22 07:23:28,960:ERROR:Traceback (most recent call last):
  File "D:\Passion Projects\PavementResearch\venv\lib\site-packages\joblib\parallel.py", line 820, in dispatch_one_batch
    tasks = self._ready_batches.get(block=False)
  File "C:\Users\lakit\AppData\Local\Programs\Python\Python38\lib\queue.py", line 167, in get
    raise Empty
_queue.Empty

During handling of the above exception, another exception occurred:

Traceback (most recent call last):
  File "D:\Passion Projects\PavementResearch\venv\lib\site-packages\pycaret\internal\tabular.py", line 2163, in compare_models
    model, model_fit_time = create_model_supervised(
  File "D:\Passion Projects\PavementResearch\venv\lib\site-packages\pycaret\internal\tabular.py", line 3112, in create_model_supervised
    scores = cross_validate(
  File "D:\Passion Projects\PavementResearch\venv\lib\site-packages\sklearn\utils\validation.py", line 72, in inner_f
    return f(**kwargs)
  File "D:\Passion Projects\PavementResearch\venv\lib\site-packages\sklearn\model_selection\_validation.py", line 242, in cross_validate
    scores = parallel(
  File "D:\Passion Projects\PavementResearch\venv\lib\site-packages\joblib\parallel.py", line 1041, in __call__
    if self.dispatch_one_batch(iterator):
  File "D:\Passion Projects\PavementResearch\venv\lib\site-packages\joblib\parallel.py", line 831, in dispatch_one_batch
    islice = list(itertools.islice(iterator, big_batch_size))
  File "D:\Passion Projects\PavementResearch\venv\lib\site-packages\sklearn\model_selection\_validation.py", line 242, in <genexpr>
    scores = parallel(
  File "D:\Passion Projects\PavementResearch\venv\lib\site-packages\sklearn\model_selection\_split.py", line 331, in split
    raise ValueError(
ValueError: Cannot have number of splits n_splits=10 greater than the number of samples: n_samples=4.

During handling of the above exception, another exception occurred:

Traceback (most recent call last):
  File "D:\Passion Projects\PavementResearch\venv\lib\site-packages\joblib\parallel.py", line 820, in dispatch_one_batch
    tasks = self._ready_batches.get(block=False)
  File "C:\Users\lakit\AppData\Local\Programs\Python\Python38\lib\queue.py", line 167, in get
    raise Empty
_queue.Empty

During handling of the above exception, another exception occurred:

Traceback (most recent call last):
  File "D:\Passion Projects\PavementResearch\venv\lib\site-packages\pycaret\internal\tabular.py", line 2183, in compare_models
    model, model_fit_time = create_model_supervised(
  File "D:\Passion Projects\PavementResearch\venv\lib\site-packages\pycaret\internal\tabular.py", line 3112, in create_model_supervised
    scores = cross_validate(
  File "D:\Passion Projects\PavementResearch\venv\lib\site-packages\sklearn\utils\validation.py", line 72, in inner_f
    return f(**kwargs)
  File "D:\Passion Projects\PavementResearch\venv\lib\site-packages\sklearn\model_selection\_validation.py", line 242, in cross_validate
    scores = parallel(
  File "D:\Passion Projects\PavementResearch\venv\lib\site-packages\joblib\parallel.py", line 1041, in __call__
    if self.dispatch_one_batch(iterator):
  File "D:\Passion Projects\PavementResearch\venv\lib\site-packages\joblib\parallel.py", line 831, in dispatch_one_batch
    islice = list(itertools.islice(iterator, big_batch_size))
  File "D:\Passion Projects\PavementResearch\venv\lib\site-packages\sklearn\model_selection\_validation.py", line 242, in <genexpr>
    scores = parallel(
  File "D:\Passion Projects\PavementResearch\venv\lib\site-packages\sklearn\model_selection\_split.py", line 331, in split
    raise ValueError(
ValueError: Cannot have number of splits n_splits=10 greater than the number of samples: n_samples=4.

2021-04-22 07:23:28,960:INFO:Initializing Decision Tree Regressor
2021-04-22 07:23:28,960:INFO:Total runtime is 0.005899910132090251 minutes
2021-04-22 07:23:28,961:INFO:SubProcess create_model() called ==================================
2021-04-22 07:23:28,962:INFO:Initializing create_model()
2021-04-22 07:23:28,962:INFO:create_model(estimator=dt, fold=KFold(n_splits=10, random_state=None, shuffle=False), round=4, cross_validation=True, predict=True, fit_kwargs={}, groups=None, refit=False, verbose=False, system=False, metrics=None, display=<pycaret.internal.Display.Display object at 0x0000025CF9FD29A0>, kwargs={})
2021-04-22 07:23:28,962:INFO:Checking exceptions
2021-04-22 07:23:28,962:INFO:Importing libraries
2021-04-22 07:23:28,962:INFO:Copying training dataset
2021-04-22 07:23:28,962:INFO:Defining folds
2021-04-22 07:23:28,962:INFO:Declaring metric variables
2021-04-22 07:23:28,964:INFO:Importing untrained model
2021-04-22 07:23:28,965:INFO:Decision Tree Regressor Imported succesfully
2021-04-22 07:23:28,969:INFO:Starting cross validation
2021-04-22 07:23:28,969:INFO:Cross validating with KFold(n_splits=10, random_state=None, shuffle=False), n_jobs=-1
2021-04-22 07:23:28,970:WARNING:create_model() for dt raised an exception or returned all 0.0, trying without fit_kwargs:
2021-04-22 07:23:28,970:WARNING:Traceback (most recent call last):
  File "D:\Passion Projects\PavementResearch\venv\lib\site-packages\joblib\parallel.py", line 820, in dispatch_one_batch
    tasks = self._ready_batches.get(block=False)
  File "C:\Users\lakit\AppData\Local\Programs\Python\Python38\lib\queue.py", line 167, in get
    raise Empty
_queue.Empty

During handling of the above exception, another exception occurred:

Traceback (most recent call last):
  File "D:\Passion Projects\PavementResearch\venv\lib\site-packages\pycaret\internal\tabular.py", line 2163, in compare_models
    model, model_fit_time = create_model_supervised(
  File "D:\Passion Projects\PavementResearch\venv\lib\site-packages\pycaret\internal\tabular.py", line 3112, in create_model_supervised
    scores = cross_validate(
  File "D:\Passion Projects\PavementResearch\venv\lib\site-packages\sklearn\utils\validation.py", line 72, in inner_f
    return f(**kwargs)
  File "D:\Passion Projects\PavementResearch\venv\lib\site-packages\sklearn\model_selection\_validation.py", line 242, in cross_validate
    scores = parallel(
  File "D:\Passion Projects\PavementResearch\venv\lib\site-packages\joblib\parallel.py", line 1041, in __call__
    if self.dispatch_one_batch(iterator):
  File "D:\Passion Projects\PavementResearch\venv\lib\site-packages\joblib\parallel.py", line 831, in dispatch_one_batch
    islice = list(itertools.islice(iterator, big_batch_size))
  File "D:\Passion Projects\PavementResearch\venv\lib\site-packages\sklearn\model_selection\_validation.py", line 242, in <genexpr>
    scores = parallel(
  File "D:\Passion Projects\PavementResearch\venv\lib\site-packages\sklearn\model_selection\_split.py", line 331, in split
    raise ValueError(
ValueError: Cannot have number of splits n_splits=10 greater than the number of samples: n_samples=4.

2021-04-22 07:23:28,970:INFO:Initializing create_model()
2021-04-22 07:23:28,970:INFO:create_model(estimator=dt, fold=KFold(n_splits=10, random_state=None, shuffle=False), round=4, cross_validation=True, predict=True, fit_kwargs=None, groups=None, refit=False, verbose=False, system=False, metrics=None, display=<pycaret.internal.Display.Display object at 0x0000025CF9FD29A0>, kwargs={})
2021-04-22 07:23:28,970:INFO:Checking exceptions
2021-04-22 07:23:28,970:INFO:Importing libraries
2021-04-22 07:23:28,970:INFO:Copying training dataset
2021-04-22 07:23:28,970:INFO:Defining folds
2021-04-22 07:23:28,971:INFO:Declaring metric variables
2021-04-22 07:23:28,972:INFO:Importing untrained model
2021-04-22 07:23:28,974:INFO:Decision Tree Regressor Imported succesfully
2021-04-22 07:23:28,977:INFO:Starting cross validation
2021-04-22 07:23:28,977:INFO:Cross validating with KFold(n_splits=10, random_state=None, shuffle=False), n_jobs=-1
2021-04-22 07:23:28,978:ERROR:create_model() for dt raised an exception:
2021-04-22 07:23:28,979:ERROR:Traceback (most recent call last):
  File "D:\Passion Projects\PavementResearch\venv\lib\site-packages\joblib\parallel.py", line 820, in dispatch_one_batch
    tasks = self._ready_batches.get(block=False)
  File "C:\Users\lakit\AppData\Local\Programs\Python\Python38\lib\queue.py", line 167, in get
    raise Empty
_queue.Empty

During handling of the above exception, another exception occurred:

Traceback (most recent call last):
  File "D:\Passion Projects\PavementResearch\venv\lib\site-packages\pycaret\internal\tabular.py", line 2163, in compare_models
    model, model_fit_time = create_model_supervised(
  File "D:\Passion Projects\PavementResearch\venv\lib\site-packages\pycaret\internal\tabular.py", line 3112, in create_model_supervised
    scores = cross_validate(
  File "D:\Passion Projects\PavementResearch\venv\lib\site-packages\sklearn\utils\validation.py", line 72, in inner_f
    return f(**kwargs)
  File "D:\Passion Projects\PavementResearch\venv\lib\site-packages\sklearn\model_selection\_validation.py", line 242, in cross_validate
    scores = parallel(
  File "D:\Passion Projects\PavementResearch\venv\lib\site-packages\joblib\parallel.py", line 1041, in __call__
    if self.dispatch_one_batch(iterator):
  File "D:\Passion Projects\PavementResearch\venv\lib\site-packages\joblib\parallel.py", line 831, in dispatch_one_batch
    islice = list(itertools.islice(iterator, big_batch_size))
  File "D:\Passion Projects\PavementResearch\venv\lib\site-packages\sklearn\model_selection\_validation.py", line 242, in <genexpr>
    scores = parallel(
  File "D:\Passion Projects\PavementResearch\venv\lib\site-packages\sklearn\model_selection\_split.py", line 331, in split
    raise ValueError(
ValueError: Cannot have number of splits n_splits=10 greater than the number of samples: n_samples=4.

During handling of the above exception, another exception occurred:

Traceback (most recent call last):
  File "D:\Passion Projects\PavementResearch\venv\lib\site-packages\joblib\parallel.py", line 820, in dispatch_one_batch
    tasks = self._ready_batches.get(block=False)
  File "C:\Users\lakit\AppData\Local\Programs\Python\Python38\lib\queue.py", line 167, in get
    raise Empty
_queue.Empty

During handling of the above exception, another exception occurred:

Traceback (most recent call last):
  File "D:\Passion Projects\PavementResearch\venv\lib\site-packages\pycaret\internal\tabular.py", line 2183, in compare_models
    model, model_fit_time = create_model_supervised(
  File "D:\Passion Projects\PavementResearch\venv\lib\site-packages\pycaret\internal\tabular.py", line 3112, in create_model_supervised
    scores = cross_validate(
  File "D:\Passion Projects\PavementResearch\venv\lib\site-packages\sklearn\utils\validation.py", line 72, in inner_f
    return f(**kwargs)
  File "D:\Passion Projects\PavementResearch\venv\lib\site-packages\sklearn\model_selection\_validation.py", line 242, in cross_validate
    scores = parallel(
  File "D:\Passion Projects\PavementResearch\venv\lib\site-packages\joblib\parallel.py", line 1041, in __call__
    if self.dispatch_one_batch(iterator):
  File "D:\Passion Projects\PavementResearch\venv\lib\site-packages\joblib\parallel.py", line 831, in dispatch_one_batch
    islice = list(itertools.islice(iterator, big_batch_size))
  File "D:\Passion Projects\PavementResearch\venv\lib\site-packages\sklearn\model_selection\_validation.py", line 242, in <genexpr>
    scores = parallel(
  File "D:\Passion Projects\PavementResearch\venv\lib\site-packages\sklearn\model_selection\_split.py", line 331, in split
    raise ValueError(
ValueError: Cannot have number of splits n_splits=10 greater than the number of samples: n_samples=4.

2021-04-22 07:23:28,979:INFO:Initializing Random Forest Regressor
2021-04-22 07:23:28,979:INFO:Total runtime is 0.0062165379524230955 minutes
2021-04-22 07:23:28,980:INFO:SubProcess create_model() called ==================================
2021-04-22 07:23:28,981:INFO:Initializing create_model()
2021-04-22 07:23:28,981:INFO:create_model(estimator=rf, fold=KFold(n_splits=10, random_state=None, shuffle=False), round=4, cross_validation=True, predict=True, fit_kwargs={}, groups=None, refit=False, verbose=False, system=False, metrics=None, display=<pycaret.internal.Display.Display object at 0x0000025CF9FD29A0>, kwargs={})
2021-04-22 07:23:28,981:INFO:Checking exceptions
2021-04-22 07:23:28,981:INFO:Importing libraries
2021-04-22 07:23:28,981:INFO:Copying training dataset
2021-04-22 07:23:28,981:INFO:Defining folds
2021-04-22 07:23:28,981:INFO:Declaring metric variables
2021-04-22 07:23:28,982:INFO:Importing untrained model
2021-04-22 07:23:28,984:INFO:Random Forest Regressor Imported succesfully
2021-04-22 07:23:28,987:INFO:Starting cross validation
2021-04-22 07:23:28,988:INFO:Cross validating with KFold(n_splits=10, random_state=None, shuffle=False), n_jobs=-1
2021-04-22 07:23:28,988:WARNING:create_model() for rf raised an exception or returned all 0.0, trying without fit_kwargs:
2021-04-22 07:23:28,989:WARNING:Traceback (most recent call last):
  File "D:\Passion Projects\PavementResearch\venv\lib\site-packages\joblib\parallel.py", line 820, in dispatch_one_batch
    tasks = self._ready_batches.get(block=False)
  File "C:\Users\lakit\AppData\Local\Programs\Python\Python38\lib\queue.py", line 167, in get
    raise Empty
_queue.Empty

During handling of the above exception, another exception occurred:

Traceback (most recent call last):
  File "D:\Passion Projects\PavementResearch\venv\lib\site-packages\pycaret\internal\tabular.py", line 2163, in compare_models
    model, model_fit_time = create_model_supervised(
  File "D:\Passion Projects\PavementResearch\venv\lib\site-packages\pycaret\internal\tabular.py", line 3112, in create_model_supervised
    scores = cross_validate(
  File "D:\Passion Projects\PavementResearch\venv\lib\site-packages\sklearn\utils\validation.py", line 72, in inner_f
    return f(**kwargs)
  File "D:\Passion Projects\PavementResearch\venv\lib\site-packages\sklearn\model_selection\_validation.py", line 242, in cross_validate
    scores = parallel(
  File "D:\Passion Projects\PavementResearch\venv\lib\site-packages\joblib\parallel.py", line 1041, in __call__
    if self.dispatch_one_batch(iterator):
  File "D:\Passion Projects\PavementResearch\venv\lib\site-packages\joblib\parallel.py", line 831, in dispatch_one_batch
    islice = list(itertools.islice(iterator, big_batch_size))
  File "D:\Passion Projects\PavementResearch\venv\lib\site-packages\sklearn\model_selection\_validation.py", line 242, in <genexpr>
    scores = parallel(
  File "D:\Passion Projects\PavementResearch\venv\lib\site-packages\sklearn\model_selection\_split.py", line 331, in split
    raise ValueError(
ValueError: Cannot have number of splits n_splits=10 greater than the number of samples: n_samples=4.

2021-04-22 07:23:28,989:INFO:Initializing create_model()
2021-04-22 07:23:28,989:INFO:create_model(estimator=rf, fold=KFold(n_splits=10, random_state=None, shuffle=False), round=4, cross_validation=True, predict=True, fit_kwargs=None, groups=None, refit=False, verbose=False, system=False, metrics=None, display=<pycaret.internal.Display.Display object at 0x0000025CF9FD29A0>, kwargs={})
2021-04-22 07:23:28,989:INFO:Checking exceptions
2021-04-22 07:23:28,989:INFO:Importing libraries
2021-04-22 07:23:28,989:INFO:Copying training dataset
2021-04-22 07:23:28,989:INFO:Defining folds
2021-04-22 07:23:28,989:INFO:Declaring metric variables
2021-04-22 07:23:28,991:INFO:Importing untrained model
2021-04-22 07:23:28,993:INFO:Random Forest Regressor Imported succesfully
2021-04-22 07:23:28,996:INFO:Starting cross validation
2021-04-22 07:23:28,996:INFO:Cross validating with KFold(n_splits=10, random_state=None, shuffle=False), n_jobs=-1
2021-04-22 07:23:28,997:ERROR:create_model() for rf raised an exception:
2021-04-22 07:23:28,997:ERROR:Traceback (most recent call last):
  File "D:\Passion Projects\PavementResearch\venv\lib\site-packages\joblib\parallel.py", line 820, in dispatch_one_batch
    tasks = self._ready_batches.get(block=False)
  File "C:\Users\lakit\AppData\Local\Programs\Python\Python38\lib\queue.py", line 167, in get
    raise Empty
_queue.Empty

During handling of the above exception, another exception occurred:

Traceback (most recent call last):
  File "D:\Passion Projects\PavementResearch\venv\lib\site-packages\pycaret\internal\tabular.py", line 2163, in compare_models
    model, model_fit_time = create_model_supervised(
  File "D:\Passion Projects\PavementResearch\venv\lib\site-packages\pycaret\internal\tabular.py", line 3112, in create_model_supervised
    scores = cross_validate(
  File "D:\Passion Projects\PavementResearch\venv\lib\site-packages\sklearn\utils\validation.py", line 72, in inner_f
    return f(**kwargs)
  File "D:\Passion Projects\PavementResearch\venv\lib\site-packages\sklearn\model_selection\_validation.py", line 242, in cross_validate
    scores = parallel(
  File "D:\Passion Projects\PavementResearch\venv\lib\site-packages\joblib\parallel.py", line 1041, in __call__
    if self.dispatch_one_batch(iterator):
  File "D:\Passion Projects\PavementResearch\venv\lib\site-packages\joblib\parallel.py", line 831, in dispatch_one_batch
    islice = list(itertools.islice(iterator, big_batch_size))
  File "D:\Passion Projects\PavementResearch\venv\lib\site-packages\sklearn\model_selection\_validation.py", line 242, in <genexpr>
    scores = parallel(
  File "D:\Passion Projects\PavementResearch\venv\lib\site-packages\sklearn\model_selection\_split.py", line 331, in split
    raise ValueError(
ValueError: Cannot have number of splits n_splits=10 greater than the number of samples: n_samples=4.

During handling of the above exception, another exception occurred:

Traceback (most recent call last):
  File "D:\Passion Projects\PavementResearch\venv\lib\site-packages\joblib\parallel.py", line 820, in dispatch_one_batch
    tasks = self._ready_batches.get(block=False)
  File "C:\Users\lakit\AppData\Local\Programs\Python\Python38\lib\queue.py", line 167, in get
    raise Empty
_queue.Empty

During handling of the above exception, another exception occurred:

Traceback (most recent call last):
  File "D:\Passion Projects\PavementResearch\venv\lib\site-packages\pycaret\internal\tabular.py", line 2183, in compare_models
    model, model_fit_time = create_model_supervised(
  File "D:\Passion Projects\PavementResearch\venv\lib\site-packages\pycaret\internal\tabular.py", line 3112, in create_model_supervised
    scores = cross_validate(
  File "D:\Passion Projects\PavementResearch\venv\lib\site-packages\sklearn\utils\validation.py", line 72, in inner_f
    return f(**kwargs)
  File "D:\Passion Projects\PavementResearch\venv\lib\site-packages\sklearn\model_selection\_validation.py", line 242, in cross_validate
    scores = parallel(
  File "D:\Passion Projects\PavementResearch\venv\lib\site-packages\joblib\parallel.py", line 1041, in __call__
    if self.dispatch_one_batch(iterator):
  File "D:\Passion Projects\PavementResearch\venv\lib\site-packages\joblib\parallel.py", line 831, in dispatch_one_batch
    islice = list(itertools.islice(iterator, big_batch_size))
  File "D:\Passion Projects\PavementResearch\venv\lib\site-packages\sklearn\model_selection\_validation.py", line 242, in <genexpr>
    scores = parallel(
  File "D:\Passion Projects\PavementResearch\venv\lib\site-packages\sklearn\model_selection\_split.py", line 331, in split
    raise ValueError(
ValueError: Cannot have number of splits n_splits=10 greater than the number of samples: n_samples=4.

2021-04-22 07:23:28,997:INFO:Initializing Extra Trees Regressor
2021-04-22 07:23:28,997:INFO:Total runtime is 0.006516484419504801 minutes
2021-04-22 07:23:28,999:INFO:SubProcess create_model() called ==================================
2021-04-22 07:23:28,999:INFO:Initializing create_model()
2021-04-22 07:23:28,999:INFO:create_model(estimator=et, fold=KFold(n_splits=10, random_state=None, shuffle=False), round=4, cross_validation=True, predict=True, fit_kwargs={}, groups=None, refit=False, verbose=False, system=False, metrics=None, display=<pycaret.internal.Display.Display object at 0x0000025CF9FD29A0>, kwargs={})
2021-04-22 07:23:28,999:INFO:Checking exceptions
2021-04-22 07:23:28,999:INFO:Importing libraries
2021-04-22 07:23:28,999:INFO:Copying training dataset
2021-04-22 07:23:29,000:INFO:Defining folds
2021-04-22 07:23:29,000:INFO:Declaring metric variables
2021-04-22 07:23:29,001:INFO:Importing untrained model
2021-04-22 07:23:29,003:INFO:Extra Trees Regressor Imported succesfully
2021-04-22 07:23:29,006:INFO:Starting cross validation
2021-04-22 07:23:29,006:INFO:Cross validating with KFold(n_splits=10, random_state=None, shuffle=False), n_jobs=-1
2021-04-22 07:23:29,007:WARNING:create_model() for et raised an exception or returned all 0.0, trying without fit_kwargs:
2021-04-22 07:23:29,007:WARNING:Traceback (most recent call last):
  File "D:\Passion Projects\PavementResearch\venv\lib\site-packages\joblib\parallel.py", line 820, in dispatch_one_batch
    tasks = self._ready_batches.get(block=False)
  File "C:\Users\lakit\AppData\Local\Programs\Python\Python38\lib\queue.py", line 167, in get
    raise Empty
_queue.Empty

During handling of the above exception, another exception occurred:

Traceback (most recent call last):
  File "D:\Passion Projects\PavementResearch\venv\lib\site-packages\pycaret\internal\tabular.py", line 2163, in compare_models
    model, model_fit_time = create_model_supervised(
  File "D:\Passion Projects\PavementResearch\venv\lib\site-packages\pycaret\internal\tabular.py", line 3112, in create_model_supervised
    scores = cross_validate(
  File "D:\Passion Projects\PavementResearch\venv\lib\site-packages\sklearn\utils\validation.py", line 72, in inner_f
    return f(**kwargs)
  File "D:\Passion Projects\PavementResearch\venv\lib\site-packages\sklearn\model_selection\_validation.py", line 242, in cross_validate
    scores = parallel(
  File "D:\Passion Projects\PavementResearch\venv\lib\site-packages\joblib\parallel.py", line 1041, in __call__
    if self.dispatch_one_batch(iterator):
  File "D:\Passion Projects\PavementResearch\venv\lib\site-packages\joblib\parallel.py", line 831, in dispatch_one_batch
    islice = list(itertools.islice(iterator, big_batch_size))
  File "D:\Passion Projects\PavementResearch\venv\lib\site-packages\sklearn\model_selection\_validation.py", line 242, in <genexpr>
    scores = parallel(
  File "D:\Passion Projects\PavementResearch\venv\lib\site-packages\sklearn\model_selection\_split.py", line 331, in split
    raise ValueError(
ValueError: Cannot have number of splits n_splits=10 greater than the number of samples: n_samples=4.

2021-04-22 07:23:29,007:INFO:Initializing create_model()
2021-04-22 07:23:29,007:INFO:create_model(estimator=et, fold=KFold(n_splits=10, random_state=None, shuffle=False), round=4, cross_validation=True, predict=True, fit_kwargs=None, groups=None, refit=False, verbose=False, system=False, metrics=None, display=<pycaret.internal.Display.Display object at 0x0000025CF9FD29A0>, kwargs={})
2021-04-22 07:23:29,008:INFO:Checking exceptions
2021-04-22 07:23:29,008:INFO:Importing libraries
2021-04-22 07:23:29,008:INFO:Copying training dataset
2021-04-22 07:23:29,008:INFO:Defining folds
2021-04-22 07:23:29,008:INFO:Declaring metric variables
2021-04-22 07:23:29,009:INFO:Importing untrained model
2021-04-22 07:23:29,011:INFO:Extra Trees Regressor Imported succesfully
2021-04-22 07:23:29,014:INFO:Starting cross validation
2021-04-22 07:23:29,015:INFO:Cross validating with KFold(n_splits=10, random_state=None, shuffle=False), n_jobs=-1
2021-04-22 07:23:29,015:ERROR:create_model() for et raised an exception:
2021-04-22 07:23:29,016:ERROR:Traceback (most recent call last):
  File "D:\Passion Projects\PavementResearch\venv\lib\site-packages\joblib\parallel.py", line 820, in dispatch_one_batch
    tasks = self._ready_batches.get(block=False)
  File "C:\Users\lakit\AppData\Local\Programs\Python\Python38\lib\queue.py", line 167, in get
    raise Empty
_queue.Empty

During handling of the above exception, another exception occurred:

Traceback (most recent call last):
  File "D:\Passion Projects\PavementResearch\venv\lib\site-packages\pycaret\internal\tabular.py", line 2163, in compare_models
    model, model_fit_time = create_model_supervised(
  File "D:\Passion Projects\PavementResearch\venv\lib\site-packages\pycaret\internal\tabular.py", line 3112, in create_model_supervised
    scores = cross_validate(
  File "D:\Passion Projects\PavementResearch\venv\lib\site-packages\sklearn\utils\validation.py", line 72, in inner_f
    return f(**kwargs)
  File "D:\Passion Projects\PavementResearch\venv\lib\site-packages\sklearn\model_selection\_validation.py", line 242, in cross_validate
    scores = parallel(
  File "D:\Passion Projects\PavementResearch\venv\lib\site-packages\joblib\parallel.py", line 1041, in __call__
    if self.dispatch_one_batch(iterator):
  File "D:\Passion Projects\PavementResearch\venv\lib\site-packages\joblib\parallel.py", line 831, in dispatch_one_batch
    islice = list(itertools.islice(iterator, big_batch_size))
  File "D:\Passion Projects\PavementResearch\venv\lib\site-packages\sklearn\model_selection\_validation.py", line 242, in <genexpr>
    scores = parallel(
  File "D:\Passion Projects\PavementResearch\venv\lib\site-packages\sklearn\model_selection\_split.py", line 331, in split
    raise ValueError(
ValueError: Cannot have number of splits n_splits=10 greater than the number of samples: n_samples=4.

During handling of the above exception, another exception occurred:

Traceback (most recent call last):
  File "D:\Passion Projects\PavementResearch\venv\lib\site-packages\joblib\parallel.py", line 820, in dispatch_one_batch
    tasks = self._ready_batches.get(block=False)
  File "C:\Users\lakit\AppData\Local\Programs\Python\Python38\lib\queue.py", line 167, in get
    raise Empty
_queue.Empty

During handling of the above exception, another exception occurred:

Traceback (most recent call last):
  File "D:\Passion Projects\PavementResearch\venv\lib\site-packages\pycaret\internal\tabular.py", line 2183, in compare_models
    model, model_fit_time = create_model_supervised(
  File "D:\Passion Projects\PavementResearch\venv\lib\site-packages\pycaret\internal\tabular.py", line 3112, in create_model_supervised
    scores = cross_validate(
  File "D:\Passion Projects\PavementResearch\venv\lib\site-packages\sklearn\utils\validation.py", line 72, in inner_f
    return f(**kwargs)
  File "D:\Passion Projects\PavementResearch\venv\lib\site-packages\sklearn\model_selection\_validation.py", line 242, in cross_validate
    scores = parallel(
  File "D:\Passion Projects\PavementResearch\venv\lib\site-packages\joblib\parallel.py", line 1041, in __call__
    if self.dispatch_one_batch(iterator):
  File "D:\Passion Projects\PavementResearch\venv\lib\site-packages\joblib\parallel.py", line 831, in dispatch_one_batch
    islice = list(itertools.islice(iterator, big_batch_size))
  File "D:\Passion Projects\PavementResearch\venv\lib\site-packages\sklearn\model_selection\_validation.py", line 242, in <genexpr>
    scores = parallel(
  File "D:\Passion Projects\PavementResearch\venv\lib\site-packages\sklearn\model_selection\_split.py", line 331, in split
    raise ValueError(
ValueError: Cannot have number of splits n_splits=10 greater than the number of samples: n_samples=4.

2021-04-22 07:23:29,016:INFO:Initializing AdaBoost Regressor
2021-04-22 07:23:29,016:INFO:Total runtime is 0.006833211580912272 minutes
2021-04-22 07:23:29,018:INFO:SubProcess create_model() called ==================================
2021-04-22 07:23:29,018:INFO:Initializing create_model()
2021-04-22 07:23:29,018:INFO:create_model(estimator=ada, fold=KFold(n_splits=10, random_state=None, shuffle=False), round=4, cross_validation=True, predict=True, fit_kwargs={}, groups=None, refit=False, verbose=False, system=False, metrics=None, display=<pycaret.internal.Display.Display object at 0x0000025CF9FD29A0>, kwargs={})
2021-04-22 07:23:29,018:INFO:Checking exceptions
2021-04-22 07:23:29,018:INFO:Importing libraries
2021-04-22 07:23:29,018:INFO:Copying training dataset
2021-04-22 07:23:29,018:INFO:Defining folds
2021-04-22 07:23:29,018:INFO:Declaring metric variables
2021-04-22 07:23:29,020:INFO:Importing untrained model
2021-04-22 07:23:29,021:INFO:AdaBoost Regressor Imported succesfully
2021-04-22 07:23:29,024:INFO:Starting cross validation
2021-04-22 07:23:29,025:INFO:Cross validating with KFold(n_splits=10, random_state=None, shuffle=False), n_jobs=-1
2021-04-22 07:23:29,025:WARNING:create_model() for ada raised an exception or returned all 0.0, trying without fit_kwargs:
2021-04-22 07:23:29,026:WARNING:Traceback (most recent call last):
  File "D:\Passion Projects\PavementResearch\venv\lib\site-packages\joblib\parallel.py", line 820, in dispatch_one_batch
    tasks = self._ready_batches.get(block=False)
  File "C:\Users\lakit\AppData\Local\Programs\Python\Python38\lib\queue.py", line 167, in get
    raise Empty
_queue.Empty

During handling of the above exception, another exception occurred:

Traceback (most recent call last):
  File "D:\Passion Projects\PavementResearch\venv\lib\site-packages\pycaret\internal\tabular.py", line 2163, in compare_models
    model, model_fit_time = create_model_supervised(
  File "D:\Passion Projects\PavementResearch\venv\lib\site-packages\pycaret\internal\tabular.py", line 3112, in create_model_supervised
    scores = cross_validate(
  File "D:\Passion Projects\PavementResearch\venv\lib\site-packages\sklearn\utils\validation.py", line 72, in inner_f
    return f(**kwargs)
  File "D:\Passion Projects\PavementResearch\venv\lib\site-packages\sklearn\model_selection\_validation.py", line 242, in cross_validate
    scores = parallel(
  File "D:\Passion Projects\PavementResearch\venv\lib\site-packages\joblib\parallel.py", line 1041, in __call__
    if self.dispatch_one_batch(iterator):
  File "D:\Passion Projects\PavementResearch\venv\lib\site-packages\joblib\parallel.py", line 831, in dispatch_one_batch
    islice = list(itertools.islice(iterator, big_batch_size))
  File "D:\Passion Projects\PavementResearch\venv\lib\site-packages\sklearn\model_selection\_validation.py", line 242, in <genexpr>
    scores = parallel(
  File "D:\Passion Projects\PavementResearch\venv\lib\site-packages\sklearn\model_selection\_split.py", line 331, in split
    raise ValueError(
ValueError: Cannot have number of splits n_splits=10 greater than the number of samples: n_samples=4.

2021-04-22 07:23:29,026:INFO:Initializing create_model()
2021-04-22 07:23:29,026:INFO:create_model(estimator=ada, fold=KFold(n_splits=10, random_state=None, shuffle=False), round=4, cross_validation=True, predict=True, fit_kwargs=None, groups=None, refit=False, verbose=False, system=False, metrics=None, display=<pycaret.internal.Display.Display object at 0x0000025CF9FD29A0>, kwargs={})
2021-04-22 07:23:29,026:INFO:Checking exceptions
2021-04-22 07:23:29,026:INFO:Importing libraries
2021-04-22 07:23:29,026:INFO:Copying training dataset
2021-04-22 07:23:29,026:INFO:Defining folds
2021-04-22 07:23:29,026:INFO:Declaring metric variables
2021-04-22 07:23:29,028:INFO:Importing untrained model
2021-04-22 07:23:29,030:INFO:AdaBoost Regressor Imported succesfully
2021-04-22 07:23:29,033:INFO:Starting cross validation
2021-04-22 07:23:29,033:INFO:Cross validating with KFold(n_splits=10, random_state=None, shuffle=False), n_jobs=-1
2021-04-22 07:23:29,034:ERROR:create_model() for ada raised an exception:
2021-04-22 07:23:29,034:ERROR:Traceback (most recent call last):
  File "D:\Passion Projects\PavementResearch\venv\lib\site-packages\joblib\parallel.py", line 820, in dispatch_one_batch
    tasks = self._ready_batches.get(block=False)
  File "C:\Users\lakit\AppData\Local\Programs\Python\Python38\lib\queue.py", line 167, in get
    raise Empty
_queue.Empty

During handling of the above exception, another exception occurred:

Traceback (most recent call last):
  File "D:\Passion Projects\PavementResearch\venv\lib\site-packages\pycaret\internal\tabular.py", line 2163, in compare_models
    model, model_fit_time = create_model_supervised(
  File "D:\Passion Projects\PavementResearch\venv\lib\site-packages\pycaret\internal\tabular.py", line 3112, in create_model_supervised
    scores = cross_validate(
  File "D:\Passion Projects\PavementResearch\venv\lib\site-packages\sklearn\utils\validation.py", line 72, in inner_f
    return f(**kwargs)
  File "D:\Passion Projects\PavementResearch\venv\lib\site-packages\sklearn\model_selection\_validation.py", line 242, in cross_validate
    scores = parallel(
  File "D:\Passion Projects\PavementResearch\venv\lib\site-packages\joblib\parallel.py", line 1041, in __call__
    if self.dispatch_one_batch(iterator):
  File "D:\Passion Projects\PavementResearch\venv\lib\site-packages\joblib\parallel.py", line 831, in dispatch_one_batch
    islice = list(itertools.islice(iterator, big_batch_size))
  File "D:\Passion Projects\PavementResearch\venv\lib\site-packages\sklearn\model_selection\_validation.py", line 242, in <genexpr>
    scores = parallel(
  File "D:\Passion Projects\PavementResearch\venv\lib\site-packages\sklearn\model_selection\_split.py", line 331, in split
    raise ValueError(
ValueError: Cannot have number of splits n_splits=10 greater than the number of samples: n_samples=4.

During handling of the above exception, another exception occurred:

Traceback (most recent call last):
  File "D:\Passion Projects\PavementResearch\venv\lib\site-packages\joblib\parallel.py", line 820, in dispatch_one_batch
    tasks = self._ready_batches.get(block=False)
  File "C:\Users\lakit\AppData\Local\Programs\Python\Python38\lib\queue.py", line 167, in get
    raise Empty
_queue.Empty

During handling of the above exception, another exception occurred:

Traceback (most recent call last):
  File "D:\Passion Projects\PavementResearch\venv\lib\site-packages\pycaret\internal\tabular.py", line 2183, in compare_models
    model, model_fit_time = create_model_supervised(
  File "D:\Passion Projects\PavementResearch\venv\lib\site-packages\pycaret\internal\tabular.py", line 3112, in create_model_supervised
    scores = cross_validate(
  File "D:\Passion Projects\PavementResearch\venv\lib\site-packages\sklearn\utils\validation.py", line 72, in inner_f
    return f(**kwargs)
  File "D:\Passion Projects\PavementResearch\venv\lib\site-packages\sklearn\model_selection\_validation.py", line 242, in cross_validate
    scores = parallel(
  File "D:\Passion Projects\PavementResearch\venv\lib\site-packages\joblib\parallel.py", line 1041, in __call__
    if self.dispatch_one_batch(iterator):
  File "D:\Passion Projects\PavementResearch\venv\lib\site-packages\joblib\parallel.py", line 831, in dispatch_one_batch
    islice = list(itertools.islice(iterator, big_batch_size))
  File "D:\Passion Projects\PavementResearch\venv\lib\site-packages\sklearn\model_selection\_validation.py", line 242, in <genexpr>
    scores = parallel(
  File "D:\Passion Projects\PavementResearch\venv\lib\site-packages\sklearn\model_selection\_split.py", line 331, in split
    raise ValueError(
ValueError: Cannot have number of splits n_splits=10 greater than the number of samples: n_samples=4.

2021-04-22 07:23:29,034:INFO:Initializing Gradient Boosting Regressor
2021-04-22 07:23:29,034:INFO:Total runtime is 0.007133213678995768 minutes
2021-04-22 07:23:29,036:INFO:SubProcess create_model() called ==================================
2021-04-22 07:23:29,036:INFO:Initializing create_model()
2021-04-22 07:23:29,036:INFO:create_model(estimator=gbr, fold=KFold(n_splits=10, random_state=None, shuffle=False), round=4, cross_validation=True, predict=True, fit_kwargs={}, groups=None, refit=False, verbose=False, system=False, metrics=None, display=<pycaret.internal.Display.Display object at 0x0000025CF9FD29A0>, kwargs={})
2021-04-22 07:23:29,036:INFO:Checking exceptions
2021-04-22 07:23:29,036:INFO:Importing libraries
2021-04-22 07:23:29,036:INFO:Copying training dataset
2021-04-22 07:23:29,038:INFO:Defining folds
2021-04-22 07:23:29,038:INFO:Declaring metric variables
2021-04-22 07:23:29,038:INFO:Importing untrained model
2021-04-22 07:23:29,040:INFO:Gradient Boosting Regressor Imported succesfully
2021-04-22 07:23:29,043:INFO:Starting cross validation
2021-04-22 07:23:29,043:INFO:Cross validating with KFold(n_splits=10, random_state=None, shuffle=False), n_jobs=-1
2021-04-22 07:23:29,044:WARNING:create_model() for gbr raised an exception or returned all 0.0, trying without fit_kwargs:
2021-04-22 07:23:29,044:WARNING:Traceback (most recent call last):
  File "D:\Passion Projects\PavementResearch\venv\lib\site-packages\joblib\parallel.py", line 820, in dispatch_one_batch
    tasks = self._ready_batches.get(block=False)
  File "C:\Users\lakit\AppData\Local\Programs\Python\Python38\lib\queue.py", line 167, in get
    raise Empty
_queue.Empty

During handling of the above exception, another exception occurred:

Traceback (most recent call last):
  File "D:\Passion Projects\PavementResearch\venv\lib\site-packages\pycaret\internal\tabular.py", line 2163, in compare_models
    model, model_fit_time = create_model_supervised(
  File "D:\Passion Projects\PavementResearch\venv\lib\site-packages\pycaret\internal\tabular.py", line 3112, in create_model_supervised
    scores = cross_validate(
  File "D:\Passion Projects\PavementResearch\venv\lib\site-packages\sklearn\utils\validation.py", line 72, in inner_f
    return f(**kwargs)
  File "D:\Passion Projects\PavementResearch\venv\lib\site-packages\sklearn\model_selection\_validation.py", line 242, in cross_validate
    scores = parallel(
  File "D:\Passion Projects\PavementResearch\venv\lib\site-packages\joblib\parallel.py", line 1041, in __call__
    if self.dispatch_one_batch(iterator):
  File "D:\Passion Projects\PavementResearch\venv\lib\site-packages\joblib\parallel.py", line 831, in dispatch_one_batch
    islice = list(itertools.islice(iterator, big_batch_size))
  File "D:\Passion Projects\PavementResearch\venv\lib\site-packages\sklearn\model_selection\_validation.py", line 242, in <genexpr>
    scores = parallel(
  File "D:\Passion Projects\PavementResearch\venv\lib\site-packages\sklearn\model_selection\_split.py", line 331, in split
    raise ValueError(
ValueError: Cannot have number of splits n_splits=10 greater than the number of samples: n_samples=4.

2021-04-22 07:23:29,044:INFO:Initializing create_model()
2021-04-22 07:23:29,044:INFO:create_model(estimator=gbr, fold=KFold(n_splits=10, random_state=None, shuffle=False), round=4, cross_validation=True, predict=True, fit_kwargs=None, groups=None, refit=False, verbose=False, system=False, metrics=None, display=<pycaret.internal.Display.Display object at 0x0000025CF9FD29A0>, kwargs={})
2021-04-22 07:23:29,044:INFO:Checking exceptions
2021-04-22 07:23:29,045:INFO:Importing libraries
2021-04-22 07:23:29,045:INFO:Copying training dataset
2021-04-22 07:23:29,045:INFO:Defining folds
2021-04-22 07:23:29,045:INFO:Declaring metric variables
2021-04-22 07:23:29,046:INFO:Importing untrained model
2021-04-22 07:23:29,048:INFO:Gradient Boosting Regressor Imported succesfully
2021-04-22 07:23:29,051:INFO:Starting cross validation
2021-04-22 07:23:29,052:INFO:Cross validating with KFold(n_splits=10, random_state=None, shuffle=False), n_jobs=-1
2021-04-22 07:23:29,052:ERROR:create_model() for gbr raised an exception:
2021-04-22 07:23:29,053:ERROR:Traceback (most recent call last):
  File "D:\Passion Projects\PavementResearch\venv\lib\site-packages\joblib\parallel.py", line 820, in dispatch_one_batch
    tasks = self._ready_batches.get(block=False)
  File "C:\Users\lakit\AppData\Local\Programs\Python\Python38\lib\queue.py", line 167, in get
    raise Empty
_queue.Empty

During handling of the above exception, another exception occurred:

Traceback (most recent call last):
  File "D:\Passion Projects\PavementResearch\venv\lib\site-packages\pycaret\internal\tabular.py", line 2163, in compare_models
    model, model_fit_time = create_model_supervised(
  File "D:\Passion Projects\PavementResearch\venv\lib\site-packages\pycaret\internal\tabular.py", line 3112, in create_model_supervised
    scores = cross_validate(
  File "D:\Passion Projects\PavementResearch\venv\lib\site-packages\sklearn\utils\validation.py", line 72, in inner_f
    return f(**kwargs)
  File "D:\Passion Projects\PavementResearch\venv\lib\site-packages\sklearn\model_selection\_validation.py", line 242, in cross_validate
    scores = parallel(
  File "D:\Passion Projects\PavementResearch\venv\lib\site-packages\joblib\parallel.py", line 1041, in __call__
    if self.dispatch_one_batch(iterator):
  File "D:\Passion Projects\PavementResearch\venv\lib\site-packages\joblib\parallel.py", line 831, in dispatch_one_batch
    islice = list(itertools.islice(iterator, big_batch_size))
  File "D:\Passion Projects\PavementResearch\venv\lib\site-packages\sklearn\model_selection\_validation.py", line 242, in <genexpr>
    scores = parallel(
  File "D:\Passion Projects\PavementResearch\venv\lib\site-packages\sklearn\model_selection\_split.py", line 331, in split
    raise ValueError(
ValueError: Cannot have number of splits n_splits=10 greater than the number of samples: n_samples=4.

During handling of the above exception, another exception occurred:

Traceback (most recent call last):
  File "D:\Passion Projects\PavementResearch\venv\lib\site-packages\joblib\parallel.py", line 820, in dispatch_one_batch
    tasks = self._ready_batches.get(block=False)
  File "C:\Users\lakit\AppData\Local\Programs\Python\Python38\lib\queue.py", line 167, in get
    raise Empty
_queue.Empty

During handling of the above exception, another exception occurred:

Traceback (most recent call last):
  File "D:\Passion Projects\PavementResearch\venv\lib\site-packages\pycaret\internal\tabular.py", line 2183, in compare_models
    model, model_fit_time = create_model_supervised(
  File "D:\Passion Projects\PavementResearch\venv\lib\site-packages\pycaret\internal\tabular.py", line 3112, in create_model_supervised
    scores = cross_validate(
  File "D:\Passion Projects\PavementResearch\venv\lib\site-packages\sklearn\utils\validation.py", line 72, in inner_f
    return f(**kwargs)
  File "D:\Passion Projects\PavementResearch\venv\lib\site-packages\sklearn\model_selection\_validation.py", line 242, in cross_validate
    scores = parallel(
  File "D:\Passion Projects\PavementResearch\venv\lib\site-packages\joblib\parallel.py", line 1041, in __call__
    if self.dispatch_one_batch(iterator):
  File "D:\Passion Projects\PavementResearch\venv\lib\site-packages\joblib\parallel.py", line 831, in dispatch_one_batch
    islice = list(itertools.islice(iterator, big_batch_size))
  File "D:\Passion Projects\PavementResearch\venv\lib\site-packages\sklearn\model_selection\_validation.py", line 242, in <genexpr>
    scores = parallel(
  File "D:\Passion Projects\PavementResearch\venv\lib\site-packages\sklearn\model_selection\_split.py", line 331, in split
    raise ValueError(
ValueError: Cannot have number of splits n_splits=10 greater than the number of samples: n_samples=4.

2021-04-22 07:23:29,053:INFO:Initializing Light Gradient Boosting Machine
2021-04-22 07:23:29,053:INFO:Total runtime is 0.007449869314829508 minutes
2021-04-22 07:23:29,056:INFO:SubProcess create_model() called ==================================
2021-04-22 07:23:29,056:INFO:Initializing create_model()
2021-04-22 07:23:29,056:INFO:create_model(estimator=lightgbm, fold=KFold(n_splits=10, random_state=None, shuffle=False), round=4, cross_validation=True, predict=True, fit_kwargs={}, groups=None, refit=False, verbose=False, system=False, metrics=None, display=<pycaret.internal.Display.Display object at 0x0000025CF9FD29A0>, kwargs={})
2021-04-22 07:23:29,056:INFO:Checking exceptions
2021-04-22 07:23:29,056:INFO:Importing libraries
2021-04-22 07:23:29,056:INFO:Copying training dataset
2021-04-22 07:23:29,056:INFO:Defining folds
2021-04-22 07:23:29,056:INFO:Declaring metric variables
2021-04-22 07:23:29,057:INFO:Importing untrained model
2021-04-22 07:23:29,059:INFO:Light Gradient Boosting Machine Imported succesfully
2021-04-22 07:23:29,062:INFO:Starting cross validation
2021-04-22 07:23:29,062:INFO:Cross validating with KFold(n_splits=10, random_state=None, shuffle=False), n_jobs=-1
2021-04-22 07:23:29,063:WARNING:create_model() for lightgbm raised an exception or returned all 0.0, trying without fit_kwargs:
2021-04-22 07:23:29,063:WARNING:Traceback (most recent call last):
  File "D:\Passion Projects\PavementResearch\venv\lib\site-packages\joblib\parallel.py", line 820, in dispatch_one_batch
    tasks = self._ready_batches.get(block=False)
  File "C:\Users\lakit\AppData\Local\Programs\Python\Python38\lib\queue.py", line 167, in get
    raise Empty
_queue.Empty

During handling of the above exception, another exception occurred:

Traceback (most recent call last):
  File "D:\Passion Projects\PavementResearch\venv\lib\site-packages\pycaret\internal\tabular.py", line 2163, in compare_models
    model, model_fit_time = create_model_supervised(
  File "D:\Passion Projects\PavementResearch\venv\lib\site-packages\pycaret\internal\tabular.py", line 3112, in create_model_supervised
    scores = cross_validate(
  File "D:\Passion Projects\PavementResearch\venv\lib\site-packages\sklearn\utils\validation.py", line 72, in inner_f
    return f(**kwargs)
  File "D:\Passion Projects\PavementResearch\venv\lib\site-packages\sklearn\model_selection\_validation.py", line 242, in cross_validate
    scores = parallel(
  File "D:\Passion Projects\PavementResearch\venv\lib\site-packages\joblib\parallel.py", line 1041, in __call__
    if self.dispatch_one_batch(iterator):
  File "D:\Passion Projects\PavementResearch\venv\lib\site-packages\joblib\parallel.py", line 831, in dispatch_one_batch
    islice = list(itertools.islice(iterator, big_batch_size))
  File "D:\Passion Projects\PavementResearch\venv\lib\site-packages\sklearn\model_selection\_validation.py", line 242, in <genexpr>
    scores = parallel(
  File "D:\Passion Projects\PavementResearch\venv\lib\site-packages\sklearn\model_selection\_split.py", line 331, in split
    raise ValueError(
ValueError: Cannot have number of splits n_splits=10 greater than the number of samples: n_samples=4.

2021-04-22 07:23:29,063:INFO:Initializing create_model()
2021-04-22 07:23:29,063:INFO:create_model(estimator=lightgbm, fold=KFold(n_splits=10, random_state=None, shuffle=False), round=4, cross_validation=True, predict=True, fit_kwargs=None, groups=None, refit=False, verbose=False, system=False, metrics=None, display=<pycaret.internal.Display.Display object at 0x0000025CF9FD29A0>, kwargs={})
2021-04-22 07:23:29,063:INFO:Checking exceptions
2021-04-22 07:23:29,063:INFO:Importing libraries
2021-04-22 07:23:29,063:INFO:Copying training dataset
2021-04-22 07:23:29,063:INFO:Defining folds
2021-04-22 07:23:29,064:INFO:Declaring metric variables
2021-04-22 07:23:29,065:INFO:Importing untrained model
2021-04-22 07:23:29,067:INFO:Light Gradient Boosting Machine Imported succesfully
2021-04-22 07:23:29,070:INFO:Starting cross validation
2021-04-22 07:23:29,070:INFO:Cross validating with KFold(n_splits=10, random_state=None, shuffle=False), n_jobs=-1
2021-04-22 07:23:29,071:ERROR:create_model() for lightgbm raised an exception:
2021-04-22 07:23:29,072:ERROR:Traceback (most recent call last):
  File "D:\Passion Projects\PavementResearch\venv\lib\site-packages\joblib\parallel.py", line 820, in dispatch_one_batch
    tasks = self._ready_batches.get(block=False)
  File "C:\Users\lakit\AppData\Local\Programs\Python\Python38\lib\queue.py", line 167, in get
    raise Empty
_queue.Empty

During handling of the above exception, another exception occurred:

Traceback (most recent call last):
  File "D:\Passion Projects\PavementResearch\venv\lib\site-packages\pycaret\internal\tabular.py", line 2163, in compare_models
    model, model_fit_time = create_model_supervised(
  File "D:\Passion Projects\PavementResearch\venv\lib\site-packages\pycaret\internal\tabular.py", line 3112, in create_model_supervised
    scores = cross_validate(
  File "D:\Passion Projects\PavementResearch\venv\lib\site-packages\sklearn\utils\validation.py", line 72, in inner_f
    return f(**kwargs)
  File "D:\Passion Projects\PavementResearch\venv\lib\site-packages\sklearn\model_selection\_validation.py", line 242, in cross_validate
    scores = parallel(
  File "D:\Passion Projects\PavementResearch\venv\lib\site-packages\joblib\parallel.py", line 1041, in __call__
    if self.dispatch_one_batch(iterator):
  File "D:\Passion Projects\PavementResearch\venv\lib\site-packages\joblib\parallel.py", line 831, in dispatch_one_batch
    islice = list(itertools.islice(iterator, big_batch_size))
  File "D:\Passion Projects\PavementResearch\venv\lib\site-packages\sklearn\model_selection\_validation.py", line 242, in <genexpr>
    scores = parallel(
  File "D:\Passion Projects\PavementResearch\venv\lib\site-packages\sklearn\model_selection\_split.py", line 331, in split
    raise ValueError(
ValueError: Cannot have number of splits n_splits=10 greater than the number of samples: n_samples=4.

During handling of the above exception, another exception occurred:

Traceback (most recent call last):
  File "D:\Passion Projects\PavementResearch\venv\lib\site-packages\joblib\parallel.py", line 820, in dispatch_one_batch
    tasks = self._ready_batches.get(block=False)
  File "C:\Users\lakit\AppData\Local\Programs\Python\Python38\lib\queue.py", line 167, in get
    raise Empty
_queue.Empty

During handling of the above exception, another exception occurred:

Traceback (most recent call last):
  File "D:\Passion Projects\PavementResearch\venv\lib\site-packages\pycaret\internal\tabular.py", line 2183, in compare_models
    model, model_fit_time = create_model_supervised(
  File "D:\Passion Projects\PavementResearch\venv\lib\site-packages\pycaret\internal\tabular.py", line 3112, in create_model_supervised
    scores = cross_validate(
  File "D:\Passion Projects\PavementResearch\venv\lib\site-packages\sklearn\utils\validation.py", line 72, in inner_f
    return f(**kwargs)
  File "D:\Passion Projects\PavementResearch\venv\lib\site-packages\sklearn\model_selection\_validation.py", line 242, in cross_validate
    scores = parallel(
  File "D:\Passion Projects\PavementResearch\venv\lib\site-packages\joblib\parallel.py", line 1041, in __call__
    if self.dispatch_one_batch(iterator):
  File "D:\Passion Projects\PavementResearch\venv\lib\site-packages\joblib\parallel.py", line 831, in dispatch_one_batch
    islice = list(itertools.islice(iterator, big_batch_size))
  File "D:\Passion Projects\PavementResearch\venv\lib\site-packages\sklearn\model_selection\_validation.py", line 242, in <genexpr>
    scores = parallel(
  File "D:\Passion Projects\PavementResearch\venv\lib\site-packages\sklearn\model_selection\_split.py", line 331, in split
    raise ValueError(
ValueError: Cannot have number of splits n_splits=10 greater than the number of samples: n_samples=4.

2021-04-22 07:23:29,074:INFO:create_model_container: 0
2021-04-22 07:23:29,074:INFO:master_model_container: 0
2021-04-22 07:23:29,074:INFO:display_container: 2
2021-04-22 07:23:29,074:INFO:[]
2021-04-22 07:23:29,074:INFO:compare_models() succesfully completed......................................
2021-04-22 07:25:54,087:INFO:PyCaret Supervised Module
2021-04-22 07:25:54,087:INFO:ML Usecase: regression
2021-04-22 07:25:54,087:INFO:version 2.3.0
2021-04-22 07:25:54,087:INFO:Initializing setup()
2021-04-22 07:25:54,087:INFO:setup(target=IWP IRI, ml_usecase=regression, available_plots={'parameter': 'Hyperparameters', 'residuals': 'Residuals', 'error': 'Prediction Error', 'cooks': 'Cooks Distance', 'rfe': 'Feature Selection', 'learning': 'Learning Curve', 'manifold': 'Manifold Learning', 'vc': 'Validation Curve', 'feature': 'Feature Importance', 'feature_all': 'Feature Importance (All)', 'tree': 'Decision Tree', 'residuals_interactive': 'Interactive Residuals'}, train_size=0.7, test_data=None, preprocess=True, imputation_type=simple, iterative_imputation_iters=5, categorical_features=None, categorical_imputation=constant, categorical_iterative_imputer=lightgbm, ordinal_features=None, high_cardinality_features=None, high_cardinality_method=frequency, numeric_features=None, numeric_imputation=mean, numeric_iterative_imputer=lightgbm, date_features=None, ignore_features=None, normalize=False, normalize_method=zscore, transformation=False, transformation_method=yeo-johnson, handle_unknown_categorical=True, unknown_categorical_method=least_frequent, pca=False, pca_method=linear, pca_components=None, ignore_low_variance=False, combine_rare_levels=False, rare_level_threshold=0.1, bin_numeric_features=None, remove_outliers=False, outliers_threshold=0.05, remove_multicollinearity=False, multicollinearity_threshold=0.9, remove_perfect_collinearity=True, create_clusters=False, cluster_iter=20, polynomial_features=False, polynomial_degree=2, trigonometry_features=False, polynomial_threshold=0.1, group_features=None, group_names=None, feature_selection=False, feature_selection_threshold=0.8, feature_selection_method=classic, feature_interaction=False, feature_ratio=False, interaction_threshold=0.01, fix_imbalance=False, fix_imbalance_method=None, transform_target=False, transform_target_method=box-cox, data_split_shuffle=True, data_split_stratify=False, fold_strategy=kfold, fold=10, fold_shuffle=False, fold_groups=None, n_jobs=-1, use_gpu=False, custom_pipeline=None, html=True, session_id=None, log_experiment=False, experiment_name=None, log_plots=False, log_profile=False, log_data=False, silent=False, verbose=True, profile=False, profile_kwargs=None, display=None)
2021-04-22 07:25:54,087:INFO:Checking environment
2021-04-22 07:25:54,087:INFO:python_version: 3.8.8
2021-04-22 07:25:54,087:INFO:python_build: ('tags/v3.8.8:024d805', 'Feb 19 2021 13:18:16')
2021-04-22 07:25:54,087:INFO:machine: AMD64
2021-04-22 07:25:54,087:INFO:platform: Windows-10-10.0.18362-SP0
2021-04-22 07:25:54,088:WARNING:cannot find psutil installation. memory not traceable. Install psutil using pip to enable memory logging.
2021-04-22 07:25:54,088:INFO:Checking libraries
2021-04-22 07:25:54,088:INFO:pd==1.2.4
2021-04-22 07:25:54,088:INFO:numpy==1.19.5
2021-04-22 07:25:54,088:INFO:sklearn==0.23.2
2021-04-22 07:25:54,088:INFO:lightgbm==3.2.1
2021-04-22 07:25:54,089:WARNING:catboost not found
2021-04-22 07:25:54,089:WARNING:xgboost not found
2021-04-22 07:25:54,347:INFO:mlflow==1.15.0
2021-04-22 07:25:54,347:INFO:Checking Exceptions
2021-04-22 07:25:54,347:INFO:Declaring global variables
2021-04-22 07:25:54,347:INFO:USI: 05e9
2021-04-22 07:25:54,347:INFO:pycaret_globals: {'target_param', 'y_test', 'master_model_container', 'X', '_all_metrics', 'imputation_regressor', 'gpu_param', 'fold_param', 'prep_pipe', 'imputation_classifier', 'X_train', 'exp_name_log', '_all_models_internal', 'create_model_container', 'transform_target_param', 'data_before_preprocess', 'USI', 'transform_target_method_param', 'stratify_param', 'fold_groups_param', 'logging_param', 'log_plots_param', 'pycaret_globals', '_all_models', 'html_param', 'fold_shuffle_param', 'experiment__', 'y_train', 'X_test', 'seed', 'display_container', '_internal_pipeline', 'fix_imbalance_param', '_available_plots', '_ml_usecase', 'iterative_imputation_iters_param', 'y', '_gpu_n_jobs_param', 'n_jobs_param', 'fold_generator', 'fix_imbalance_method_param'}
2021-04-22 07:25:54,347:INFO:Preparing display monitor
2021-04-22 07:25:54,347:INFO:Preparing display monitor
2021-04-22 07:25:54,352:INFO:Importing libraries
2021-04-22 07:25:54,352:INFO:Copying data for preprocessing
2021-04-22 07:25:54,354:INFO:Declaring preprocessing parameters
2021-04-22 07:25:54,354:INFO:Creating preprocessing pipeline
2021-04-22 07:25:54,369:INFO:Preprocessing pipeline created successfully
2021-04-22 07:25:54,369:ERROR:(Process Exit): setup has been interupted with user command 'quit'. setup must rerun.
2021-04-22 07:25:54,369:INFO:Creating global containers
2021-04-22 07:25:54,369:INFO:Internal pipeline: Pipeline(memory=None, steps=[('empty_step', 'passthrough')], verbose=False)
2021-04-22 07:26:00,103:WARNING:Couldn't import xgboost.XGBRegressor
2021-04-22 07:26:00,104:WARNING:Couldn't import catboost.CatBoostRegressor
2021-04-22 07:26:00,185:WARNING:Couldn't import xgboost.XGBRegressor
2021-04-22 07:26:00,185:WARNING:Couldn't import catboost.CatBoostRegressor
2021-04-22 07:26:00,186:INFO:Creating grid variables
2021-04-22 07:26:00,188:INFO:create_model_container: 0
2021-04-22 07:26:00,188:INFO:master_model_container: 0
2021-04-22 07:26:00,188:INFO:display_container: 1
2021-04-22 07:26:00,191:INFO:Pipeline(memory=None,
         steps=[('dtypes',
                 DataTypes_Auto_infer(categorical_features=[],
                                      display_types=True, features_todrop=[],
                                      id_columns=['Year', 'Survey year'],
                                      ml_usecase='regression',
                                      numerical_features=[], target='IWP IRI',
                                      time_features=[])),
                ('imputer',
                 Simple_Imputer(categorical_strategy='not_available',
                                fill_value_categorical=None,
                                fill_value_numerical=Non...
                ('scaling', 'passthrough'), ('P_transform', 'passthrough'),
                ('binn', 'passthrough'), ('rem_outliers', 'passthrough'),
                ('cluster_all', 'passthrough'),
                ('dummy', Dummify(target='IWP IRI')),
                ('fix_perfect', Remove_100(target='IWP IRI')),
                ('clean_names', Clean_Colum_Names()),
                ('feature_select', 'passthrough'), ('fix_multi', 'passthrough'),
                ('dfs', 'passthrough'), ('pca', 'passthrough')],
         verbose=False)
2021-04-22 07:26:00,191:INFO:setup() succesfully completed......................................
2021-04-22 07:26:00,236:INFO:Initializing create_model()
2021-04-22 07:26:00,236:INFO:create_model(estimator=lr, fold=None, round=4, cross_validation=True, predict=True, fit_kwargs=None, groups=None, refit=True, verbose=True, system=True, metrics=None, display=None, kwargs={})
2021-04-22 07:26:00,236:INFO:Checking exceptions
2021-04-22 07:26:00,236:INFO:Preparing display monitor
2021-04-22 07:26:00,243:INFO:Importing libraries
2021-04-22 07:26:00,243:INFO:Copying training dataset
2021-04-22 07:26:00,243:INFO:Defining folds
2021-04-22 07:26:00,243:INFO:Declaring metric variables
2021-04-22 07:26:00,248:INFO:Importing untrained model
2021-04-22 07:26:00,253:INFO:Linear Regression Imported succesfully
2021-04-22 07:26:00,263:INFO:Starting cross validation
2021-04-22 07:26:00,266:INFO:Cross validating with KFold(n_splits=10, random_state=None, shuffle=False), n_jobs=-1
